[2023-11-23T00:02:14.933+0000] {taskinstance.py:1159} INFO - Dependencies all met for dep_context=non-requeueable deps ti=<TaskInstance: outcomes_dag.Load_to_staging scheduled__2023-11-22T00:00:00+00:00 [queued]>
[2023-11-23T00:02:14.939+0000] {taskinstance.py:1159} INFO - Dependencies all met for dep_context=requeueable deps ti=<TaskInstance: outcomes_dag.Load_to_staging scheduled__2023-11-22T00:00:00+00:00 [queued]>
[2023-11-23T00:02:14.939+0000] {taskinstance.py:1361} INFO - Starting attempt 3 of 4
[2023-11-23T00:02:14.947+0000] {taskinstance.py:1382} INFO - Executing <Task(PythonOperator): Load_to_staging> on 2023-11-22 00:00:00+00:00
[2023-11-23T00:02:14.954+0000] {standard_task_runner.py:57} INFO - Started process 816 to run task
[2023-11-23T00:02:14.957+0000] {standard_task_runner.py:84} INFO - Running: ['***', 'tasks', 'run', 'outcomes_dag', 'Load_to_staging', 'scheduled__2023-11-22T00:00:00+00:00', '--job-id', '158', '--raw', '--subdir', 'DAGS_FOLDER/outcomes_dag.py', '--cfg-path', '/tmp/tmp22bd8rxe']
[2023-11-23T00:02:14.960+0000] {standard_task_runner.py:85} INFO - Job 158: Subtask Load_to_staging
[2023-11-23T00:02:14.997+0000] {task_command.py:416} INFO - Running <TaskInstance: outcomes_dag.Load_to_staging scheduled__2023-11-22T00:00:00+00:00 [running]> on host 371cae71aa63
[2023-11-23T00:02:15.044+0000] {taskinstance.py:1662} INFO - Exporting env vars: AIRFLOW_CTX_DAG_OWNER='***' AIRFLOW_CTX_DAG_ID='outcomes_dag' AIRFLOW_CTX_TASK_ID='Load_to_staging' AIRFLOW_CTX_EXECUTION_DATE='2023-11-22T00:00:00+00:00' AIRFLOW_CTX_TRY_NUMBER='3' AIRFLOW_CTX_DAG_RUN_ID='scheduled__2023-11-22T00:00:00+00:00'
[2023-11-23T00:02:15.780+0000] {taskinstance.py:1937} ERROR - Task failed with exception
Traceback (most recent call last):
  File "/home/airflow/.local/lib/python3.8/site-packages/airflow/operators/python.py", line 192, in execute
    return_value = self.execute_callable()
  File "/home/airflow/.local/lib/python3.8/site-packages/airflow/operators/python.py", line 209, in execute_callable
    return self.python_callable(*self.op_args, **self.op_kwargs)
  File "/opt/airflow/dags/ETL/load.py", line 31, in data_to_staging
    load_job = client.load_table_from_uri(uri, table_ref, job_config=job_config)
  File "/home/airflow/.local/lib/python3.8/site-packages/google/cloud/bigquery/client.py", line 2375, in load_table_from_uri
    load_job._begin(retry=retry, timeout=timeout)
  File "/home/airflow/.local/lib/python3.8/site-packages/google/cloud/bigquery/job/base.py", line 693, in _begin
    api_response = client._call_api(
  File "/home/airflow/.local/lib/python3.8/site-packages/google/cloud/bigquery/client.py", line 808, in _call_api
    return call()
  File "/home/airflow/.local/lib/python3.8/site-packages/google/api_core/retry.py", line 366, in retry_wrapped_func
    return retry_target(
  File "/home/airflow/.local/lib/python3.8/site-packages/google/api_core/retry.py", line 204, in retry_target
    return target()
  File "/home/airflow/.local/lib/python3.8/site-packages/google/cloud/_http/__init__.py", line 494, in api_request
    raise exceptions.from_http_response(response)
google.api_core.exceptions.BadRequest: 400 POST https://bigquery.googleapis.com/bigquery/v2/projects/DCSC-warehouse/jobs?prettyPrint=false: ProjectId and DatasetId must be non-empty
[2023-11-23T00:02:15.791+0000] {taskinstance.py:1400} INFO - Marking task as UP_FOR_RETRY. dag_id=outcomes_dag, task_id=Load_to_staging, execution_date=20231122T000000, start_date=20231123T000214, end_date=20231123T000215
[2023-11-23T00:02:15.798+0000] {standard_task_runner.py:104} ERROR - Failed to execute job 158 for task Load_to_staging (400 POST https://bigquery.googleapis.com/bigquery/v2/projects/DCSC-warehouse/jobs?prettyPrint=false: ProjectId and DatasetId must be non-empty; 816)
[2023-11-23T00:02:15.818+0000] {local_task_job_runner.py:228} INFO - Task exited with return code 1
[2023-11-23T00:45:21.144+0000] {taskinstance.py:1159} INFO - Dependencies all met for dep_context=non-requeueable deps ti=<TaskInstance: outcomes_dag.Load_to_staging scheduled__2023-11-22T00:00:00+00:00 [queued]>
[2023-11-23T00:45:21.150+0000] {taskinstance.py:1159} INFO - Dependencies all met for dep_context=requeueable deps ti=<TaskInstance: outcomes_dag.Load_to_staging scheduled__2023-11-22T00:00:00+00:00 [queued]>
[2023-11-23T00:45:21.150+0000] {taskinstance.py:1361} INFO - Starting attempt 3 of 4
[2023-11-23T00:45:21.160+0000] {taskinstance.py:1382} INFO - Executing <Task(PythonOperator): Load_to_staging> on 2023-11-22 00:00:00+00:00
[2023-11-23T00:45:21.168+0000] {standard_task_runner.py:57} INFO - Started process 592 to run task
[2023-11-23T00:45:21.174+0000] {standard_task_runner.py:84} INFO - Running: ['***', 'tasks', 'run', 'outcomes_dag', 'Load_to_staging', 'scheduled__2023-11-22T00:00:00+00:00', '--job-id', '146', '--raw', '--subdir', 'DAGS_FOLDER/outcomes_dag.py', '--cfg-path', '/tmp/tmpl7yhus2g']
[2023-11-23T00:45:21.178+0000] {standard_task_runner.py:85} INFO - Job 146: Subtask Load_to_staging
[2023-11-23T00:45:21.236+0000] {task_command.py:416} INFO - Running <TaskInstance: outcomes_dag.Load_to_staging scheduled__2023-11-22T00:00:00+00:00 [running]> on host 75913536581a
[2023-11-23T00:45:21.311+0000] {taskinstance.py:1662} INFO - Exporting env vars: AIRFLOW_CTX_DAG_OWNER='***' AIRFLOW_CTX_DAG_ID='outcomes_dag' AIRFLOW_CTX_TASK_ID='Load_to_staging' AIRFLOW_CTX_EXECUTION_DATE='2023-11-22T00:00:00+00:00' AIRFLOW_CTX_TRY_NUMBER='3' AIRFLOW_CTX_DAG_RUN_ID='scheduled__2023-11-22T00:00:00+00:00'
[2023-11-23T00:45:21.937+0000] {taskinstance.py:1937} ERROR - Task failed with exception
Traceback (most recent call last):
  File "/home/airflow/.local/lib/python3.8/site-packages/airflow/operators/python.py", line 192, in execute
    return_value = self.execute_callable()
  File "/home/airflow/.local/lib/python3.8/site-packages/airflow/operators/python.py", line 209, in execute_callable
    return self.python_callable(*self.op_args, **self.op_kwargs)
  File "/opt/airflow/dags/ETL/load.py", line 35, in data_to_staging
    load_job.result()  # Wait for the job to complete
  File "/home/airflow/.local/lib/python3.8/site-packages/google/cloud/bigquery/job/base.py", line 922, in result
    return super(_AsyncJob, self).result(timeout=timeout, **kwargs)
  File "/home/airflow/.local/lib/python3.8/site-packages/google/api_core/future/polling.py", line 261, in result
    raise self._exception
google.api_core.exceptions.BadRequest: 400 No schema specified on job or table.
[2023-11-23T00:45:21.954+0000] {taskinstance.py:1400} INFO - Marking task as UP_FOR_RETRY. dag_id=outcomes_dag, task_id=Load_to_staging, execution_date=20231122T000000, start_date=20231123T004521, end_date=20231123T004521
[2023-11-23T00:45:21.961+0000] {standard_task_runner.py:104} ERROR - Failed to execute job 146 for task Load_to_staging (400 No schema specified on job or table.; 592)
[2023-11-23T00:45:22.001+0000] {local_task_job_runner.py:228} INFO - Task exited with return code 1
