[2023-11-20T23:17:51.041+0000] {taskinstance.py:1159} INFO - Dependencies all met for dep_context=non-requeueable deps ti=<TaskInstance: outcomes_dag.transform manual__2023-11-20T23:17:47.940616+00:00 [queued]>
[2023-11-20T23:17:51.045+0000] {taskinstance.py:1159} INFO - Dependencies all met for dep_context=requeueable deps ti=<TaskInstance: outcomes_dag.transform manual__2023-11-20T23:17:47.940616+00:00 [queued]>
[2023-11-20T23:17:51.045+0000] {taskinstance.py:1361} INFO - Starting attempt 1 of 1
[2023-11-20T23:17:51.051+0000] {taskinstance.py:1382} INFO - Executing <Task(PythonOperator): transform> on 2023-11-20 23:17:47.940616+00:00
[2023-11-20T23:17:51.055+0000] {standard_task_runner.py:57} INFO - Started process 1417 to run task
[2023-11-20T23:17:51.058+0000] {standard_task_runner.py:84} INFO - Running: ['***', 'tasks', 'run', 'outcomes_dag', 'transform', 'manual__2023-11-20T23:17:47.940616+00:00', '--job-id', '53', '--raw', '--subdir', 'DAGS_FOLDER/outcomes_dag.py', '--cfg-path', '/tmp/tmp4lj72t3y']
[2023-11-20T23:17:51.060+0000] {standard_task_runner.py:85} INFO - Job 53: Subtask transform
[2023-11-20T23:17:51.089+0000] {task_command.py:416} INFO - Running <TaskInstance: outcomes_dag.transform manual__2023-11-20T23:17:47.940616+00:00 [running]> on host 323903d45442
[2023-11-20T23:17:51.238+0000] {taskinstance.py:1662} INFO - Exporting env vars: AIRFLOW_CTX_DAG_OWNER='***' AIRFLOW_CTX_DAG_ID='outcomes_dag' AIRFLOW_CTX_TASK_ID='transform' AIRFLOW_CTX_EXECUTION_DATE='2023-11-20T23:17:47.940616+00:00' AIRFLOW_CTX_TRY_NUMBER='1' AIRFLOW_CTX_DAG_RUN_ID='manual__2023-11-20T23:17:47.940616+00:00'
[2023-11-20T23:17:51.238+0000] {taskinstance.py:1937} ERROR - Task failed with exception
Traceback (most recent call last):
  File "/home/airflow/.local/lib/python3.8/site-packages/airflow/operators/python.py", line 192, in execute
    return_value = self.execute_callable()
  File "/home/airflow/.local/lib/python3.8/site-packages/airflow/operators/python.py", line 209, in execute_callable
    return self.python_callable(*self.op_args, **self.op_kwargs)
  File "/opt/airflow/dags/ETL/Transform.py", line 9, in transform_data
    r = requests.get(source)
NameError: name 'source' is not defined
[2023-11-20T23:17:51.245+0000] {taskinstance.py:1400} INFO - Marking task as FAILED. dag_id=outcomes_dag, task_id=transform, execution_date=20231120T231747, start_date=20231120T231751, end_date=20231120T231751
[2023-11-20T23:17:51.250+0000] {standard_task_runner.py:104} ERROR - Failed to execute job 53 for task transform (name 'source' is not defined; 1417)
[2023-11-20T23:17:51.274+0000] {local_task_job_runner.py:228} INFO - Task exited with return code 1
[2023-11-20T23:17:51.285+0000] {taskinstance.py:2778} INFO - 0 downstream tasks scheduled from follow-on schedule check
