[2023-11-20T23:19:21.769+0000] {taskinstance.py:1159} INFO - Dependencies all met for dep_context=non-requeueable deps ti=<TaskInstance: outcomes_dag.transform manual__2023-11-20T23:17:47.940616+00:00 [queued]>
[2023-11-20T23:19:21.774+0000] {taskinstance.py:1159} INFO - Dependencies all met for dep_context=requeueable deps ti=<TaskInstance: outcomes_dag.transform manual__2023-11-20T23:17:47.940616+00:00 [queued]>
[2023-11-20T23:19:21.774+0000] {taskinstance.py:1361} INFO - Starting attempt 3 of 3
[2023-11-20T23:19:21.779+0000] {taskinstance.py:1382} INFO - Executing <Task(PythonOperator): transform> on 2023-11-20 23:17:47.940616+00:00
[2023-11-20T23:19:21.783+0000] {standard_task_runner.py:57} INFO - Started process 1447 to run task
[2023-11-20T23:19:21.787+0000] {standard_task_runner.py:84} INFO - Running: ['***', 'tasks', 'run', 'outcomes_dag', 'transform', 'manual__2023-11-20T23:17:47.940616+00:00', '--job-id', '55', '--raw', '--subdir', 'DAGS_FOLDER/outcomes_dag.py', '--cfg-path', '/tmp/tmp9ep6633b']
[2023-11-20T23:19:21.790+0000] {standard_task_runner.py:85} INFO - Job 55: Subtask transform
[2023-11-20T23:19:21.822+0000] {task_command.py:416} INFO - Running <TaskInstance: outcomes_dag.transform manual__2023-11-20T23:17:47.940616+00:00 [running]> on host 323903d45442
[2023-11-20T23:19:22.253+0000] {taskinstance.py:1662} INFO - Exporting env vars: AIRFLOW_CTX_DAG_OWNER='***' AIRFLOW_CTX_DAG_ID='outcomes_dag' AIRFLOW_CTX_TASK_ID='transform' AIRFLOW_CTX_EXECUTION_DATE='2023-11-20T23:17:47.940616+00:00' AIRFLOW_CTX_TRY_NUMBER='3' AIRFLOW_CTX_DAG_RUN_ID='manual__2023-11-20T23:17:47.940616+00:00'
[2023-11-20T23:19:22.257+0000] {taskinstance.py:1937} ERROR - Task failed with exception
Traceback (most recent call last):
  File "/home/airflow/.local/lib/python3.8/site-packages/airflow/operators/python.py", line 192, in execute
    return_value = self.execute_callable()
  File "/home/airflow/.local/lib/python3.8/site-packages/airflow/operators/python.py", line 209, in execute_callable
    return self.python_callable(*self.op_args, **self.op_kwargs)
  File "/opt/airflow/dags/ETL/Transform.py", line 9, in transform_data
    r = requests.get(source_endpoint)
  File "/home/airflow/.local/lib/python3.8/site-packages/requests/api.py", line 73, in get
    return request("get", url, params=params, **kwargs)
  File "/home/airflow/.local/lib/python3.8/site-packages/requests/api.py", line 59, in request
    return session.request(method=method, url=url, **kwargs)
  File "/home/airflow/.local/lib/python3.8/site-packages/requests/sessions.py", line 575, in request
    prep = self.prepare_request(req)
  File "/home/airflow/.local/lib/python3.8/site-packages/requests/sessions.py", line 486, in prepare_request
    p.prepare(
  File "/home/airflow/.local/lib/python3.8/site-packages/requests/models.py", line 368, in prepare
    self.prepare_url(url, params)
  File "/home/airflow/.local/lib/python3.8/site-packages/requests/models.py", line 439, in prepare_url
    raise MissingSchema(
requests.exceptions.MissingSchema: Invalid URL '/opt/***/data/2023-11-20/downloads/outcomes_2023-11-20.json': No scheme supplied. Perhaps you meant https:///opt/***/data/2023-11-20/downloads/outcomes_2023-11-20.json?
[2023-11-20T23:19:22.267+0000] {taskinstance.py:1400} INFO - Marking task as FAILED. dag_id=outcomes_dag, task_id=transform, execution_date=20231120T231747, start_date=20231120T231921, end_date=20231120T231922
[2023-11-20T23:19:22.273+0000] {standard_task_runner.py:104} ERROR - Failed to execute job 55 for task transform (Invalid URL '/opt/***/data/2023-11-20/downloads/outcomes_2023-11-20.json': No scheme supplied. Perhaps you meant https:///opt/***/data/2023-11-20/downloads/outcomes_2023-11-20.json?; 1447)
[2023-11-20T23:19:22.294+0000] {local_task_job_runner.py:228} INFO - Task exited with return code 1
[2023-11-20T23:19:22.309+0000] {taskinstance.py:2778} INFO - 0 downstream tasks scheduled from follow-on schedule check
