[2023-11-22T03:19:08.761+0000] {taskinstance.py:1159} INFO - Dependencies all met for dep_context=non-requeueable deps ti=<TaskInstance: outcomes_dag.Transform manual__2023-11-22T02:53:53.928907+00:00 [queued]>
[2023-11-22T03:19:08.766+0000] {taskinstance.py:1159} INFO - Dependencies all met for dep_context=requeueable deps ti=<TaskInstance: outcomes_dag.Transform manual__2023-11-22T02:53:53.928907+00:00 [queued]>
[2023-11-22T03:19:08.766+0000] {taskinstance.py:1361} INFO - Starting attempt 3 of 3
[2023-11-22T03:19:08.771+0000] {taskinstance.py:1382} INFO - Executing <Task(PythonOperator): Transform> on 2023-11-22 02:53:53.928907+00:00
[2023-11-22T03:19:08.778+0000] {standard_task_runner.py:57} INFO - Started process 516 to run task
[2023-11-22T03:19:08.781+0000] {standard_task_runner.py:84} INFO - Running: ['***', 'tasks', 'run', 'outcomes_dag', 'Transform', 'manual__2023-11-22T02:53:53.928907+00:00', '--job-id', '27', '--raw', '--subdir', 'DAGS_FOLDER/outcomes_dag.py', '--cfg-path', '/tmp/tmpxh5whrr2']
[2023-11-22T03:19:08.784+0000] {standard_task_runner.py:85} INFO - Job 27: Subtask Transform
[2023-11-22T03:19:08.832+0000] {task_command.py:416} INFO - Running <TaskInstance: outcomes_dag.Transform manual__2023-11-22T02:53:53.928907+00:00 [running]> on host 24b88ba10398
[2023-11-22T03:19:08.880+0000] {taskinstance.py:1662} INFO - Exporting env vars: AIRFLOW_CTX_DAG_OWNER='***' AIRFLOW_CTX_DAG_ID='outcomes_dag' AIRFLOW_CTX_TASK_ID='Transform' AIRFLOW_CTX_EXECUTION_DATE='2023-11-22T02:53:53.928907+00:00' AIRFLOW_CTX_TRY_NUMBER='3' AIRFLOW_CTX_DAG_RUN_ID='manual__2023-11-22T02:53:53.928907+00:00'
[2023-11-22T03:19:08.881+0000] {logging_mixin.py:154} INFO - Getting data from Cloud Storage
[2023-11-22T03:19:09.350+0000] {logging_mixin.py:154} INFO - RangeIndex(start=0, stop=0, step=1)
[2023-11-22T03:19:09.351+0000] {taskinstance.py:1937} ERROR - Task failed with exception
Traceback (most recent call last):
  File "/home/airflow/.local/lib/python3.8/site-packages/airflow/operators/python.py", line 192, in execute
    return_value = self.execute_callable()
  File "/home/airflow/.local/lib/python3.8/site-packages/airflow/operators/python.py", line 209, in execute_callable
    return self.python_callable(*self.op_args, **self.op_kwargs)
  File "/opt/airflow/dags/ETL/Transform.py", line 11, in transform_data
    new_data = pre_process(df)
  File "/opt/airflow/dags/ETL/Transform.py", line 24, in pre_process
    df["datetime"] = pd.to_datetime(df["datetime"])
  File "/home/airflow/.local/lib/python3.8/site-packages/pandas/core/frame.py", line 3761, in __getitem__
    indexer = self.columns.get_loc(key)
  File "/home/airflow/.local/lib/python3.8/site-packages/pandas/core/indexes/range.py", line 349, in get_loc
    raise KeyError(key)
KeyError: 'datetime'
[2023-11-22T03:19:09.362+0000] {taskinstance.py:1400} INFO - Marking task as FAILED. dag_id=outcomes_dag, task_id=Transform, execution_date=20231122T025353, start_date=20231122T031908, end_date=20231122T031909
[2023-11-22T03:19:09.368+0000] {standard_task_runner.py:104} ERROR - Failed to execute job 27 for task Transform ('datetime'; 516)
[2023-11-22T03:19:09.384+0000] {local_task_job_runner.py:228} INFO - Task exited with return code 1
