[2023-11-22T23:00:08.149+0000] {taskinstance.py:1159} INFO - Dependencies all met for dep_context=non-requeueable deps ti=<TaskInstance: outcomes_dag.Load_to_staging scheduled__2023-11-08T00:00:00+00:00 [queued]>
[2023-11-22T23:00:08.173+0000] {taskinstance.py:1159} INFO - Dependencies all met for dep_context=requeueable deps ti=<TaskInstance: outcomes_dag.Load_to_staging scheduled__2023-11-08T00:00:00+00:00 [queued]>
[2023-11-22T23:00:08.189+0000] {taskinstance.py:1361} INFO - Starting attempt 1 of 4
[2023-11-22T23:00:08.234+0000] {taskinstance.py:1382} INFO - Executing <Task(PythonOperator): Load_to_staging> on 2023-11-08 00:00:00+00:00
[2023-11-22T23:00:08.261+0000] {standard_task_runner.py:57} INFO - Started process 253 to run task
[2023-11-22T23:00:08.272+0000] {standard_task_runner.py:84} INFO - Running: ['***', 'tasks', 'run', 'outcomes_dag', 'Load_to_staging', 'scheduled__2023-11-08T00:00:00+00:00', '--job-id', '61', '--raw', '--subdir', 'DAGS_FOLDER/outcomes_dag.py', '--cfg-path', '/tmp/tmp11h_fhyi']
[2023-11-22T23:00:08.279+0000] {standard_task_runner.py:85} INFO - Job 61: Subtask Load_to_staging
[2023-11-22T23:00:08.402+0000] {task_command.py:416} INFO - Running <TaskInstance: outcomes_dag.Load_to_staging scheduled__2023-11-08T00:00:00+00:00 [running]> on host 4b2f5af281f8
[2023-11-22T23:00:08.560+0000] {taskinstance.py:1662} INFO - Exporting env vars: AIRFLOW_CTX_DAG_OWNER='***' AIRFLOW_CTX_DAG_ID='outcomes_dag' AIRFLOW_CTX_TASK_ID='Load_to_staging' AIRFLOW_CTX_EXECUTION_DATE='2023-11-08T00:00:00+00:00' AIRFLOW_CTX_TRY_NUMBER='1' AIRFLOW_CTX_DAG_RUN_ID='scheduled__2023-11-08T00:00:00+00:00'
[2023-11-22T23:00:08.986+0000] {taskinstance.py:1937} ERROR - Task failed with exception
Traceback (most recent call last):
  File "/home/airflow/.local/lib/python3.8/site-packages/airflow/operators/python.py", line 192, in execute
    return_value = self.execute_callable()
  File "/home/airflow/.local/lib/python3.8/site-packages/airflow/operators/python.py", line 209, in execute_callable
    return self.python_callable(*self.op_args, **self.op_kwargs)
  File "/opt/airflow/dags/ETL/load.py", line 31, in data_to_staging
    load_job = client.load_table_from_uri(uri, table_ref, job_config=job_config)
  File "/home/airflow/.local/lib/python3.8/site-packages/google/cloud/bigquery/client.py", line 2375, in load_table_from_uri
    load_job._begin(retry=retry, timeout=timeout)
  File "/home/airflow/.local/lib/python3.8/site-packages/google/cloud/bigquery/job/base.py", line 693, in _begin
    api_response = client._call_api(
  File "/home/airflow/.local/lib/python3.8/site-packages/google/cloud/bigquery/client.py", line 808, in _call_api
    return call()
  File "/home/airflow/.local/lib/python3.8/site-packages/google/api_core/retry.py", line 366, in retry_wrapped_func
    return retry_target(
  File "/home/airflow/.local/lib/python3.8/site-packages/google/api_core/retry.py", line 204, in retry_target
    return target()
  File "/home/airflow/.local/lib/python3.8/site-packages/google/cloud/_http/__init__.py", line 494, in api_request
    raise exceptions.from_http_response(response)
google.api_core.exceptions.NotFound: 404 POST https://bigquery.googleapis.com/bigquery/v2/projects/dcsc-warehouse/jobs?prettyPrint=false: Not found: Dataset dcsc-warehouse:dcsc-warehouse.shelter_warehouse_schema
[2023-11-22T23:00:08.997+0000] {taskinstance.py:1400} INFO - Marking task as UP_FOR_RETRY. dag_id=outcomes_dag, task_id=Load_to_staging, execution_date=20231108T000000, start_date=20231122T230008, end_date=20231122T230008
[2023-11-22T23:00:09.006+0000] {standard_task_runner.py:104} ERROR - Failed to execute job 61 for task Load_to_staging (404 POST https://bigquery.googleapis.com/bigquery/v2/projects/dcsc-warehouse/jobs?prettyPrint=false: Not found: Dataset dcsc-warehouse:dcsc-warehouse.shelter_warehouse_schema; 253)
[2023-11-22T23:00:09.028+0000] {local_task_job_runner.py:228} INFO - Task exited with return code 1
[2023-11-22T23:20:25.205+0000] {taskinstance.py:1159} INFO - Dependencies all met for dep_context=non-requeueable deps ti=<TaskInstance: outcomes_dag.Load_to_staging scheduled__2023-11-08T00:00:00+00:00 [queued]>
[2023-11-22T23:20:25.215+0000] {taskinstance.py:1159} INFO - Dependencies all met for dep_context=requeueable deps ti=<TaskInstance: outcomes_dag.Load_to_staging scheduled__2023-11-08T00:00:00+00:00 [queued]>
[2023-11-22T23:20:25.216+0000] {taskinstance.py:1361} INFO - Starting attempt 1 of 4
[2023-11-22T23:20:25.241+0000] {taskinstance.py:1382} INFO - Executing <Task(PythonOperator): Load_to_staging> on 2023-11-08 00:00:00+00:00
[2023-11-22T23:20:25.265+0000] {standard_task_runner.py:84} INFO - Running: ['***', 'tasks', 'run', 'outcomes_dag', 'Load_to_staging', 'scheduled__2023-11-08T00:00:00+00:00', '--job-id', '45', '--raw', '--subdir', 'DAGS_FOLDER/outcomes_dag.py', '--cfg-path', '/tmp/tmp2wjwn24s']
[2023-11-22T23:20:25.267+0000] {standard_task_runner.py:85} INFO - Job 45: Subtask Load_to_staging
[2023-11-22T23:20:25.259+0000] {standard_task_runner.py:57} INFO - Started process 196 to run task
[2023-11-22T23:20:25.403+0000] {task_command.py:416} INFO - Running <TaskInstance: outcomes_dag.Load_to_staging scheduled__2023-11-08T00:00:00+00:00 [running]> on host b410bfb4af5e
[2023-11-22T23:20:25.482+0000] {taskinstance.py:1662} INFO - Exporting env vars: AIRFLOW_CTX_DAG_OWNER='***' AIRFLOW_CTX_DAG_ID='outcomes_dag' AIRFLOW_CTX_TASK_ID='Load_to_staging' AIRFLOW_CTX_EXECUTION_DATE='2023-11-08T00:00:00+00:00' AIRFLOW_CTX_TRY_NUMBER='1' AIRFLOW_CTX_DAG_RUN_ID='scheduled__2023-11-08T00:00:00+00:00'
[2023-11-22T23:20:25.906+0000] {taskinstance.py:1937} ERROR - Task failed with exception
Traceback (most recent call last):
  File "/home/airflow/.local/lib/python3.8/site-packages/airflow/operators/python.py", line 192, in execute
    return_value = self.execute_callable()
  File "/home/airflow/.local/lib/python3.8/site-packages/airflow/operators/python.py", line 209, in execute_callable
    return self.python_callable(*self.op_args, **self.op_kwargs)
  File "/opt/airflow/dags/ETL/load.py", line 33, in data_to_staging
    load_job.result()  # Wait for the job to complete
  File "/home/airflow/.local/lib/python3.8/site-packages/google/cloud/bigquery/job/base.py", line 922, in result
    return super(_AsyncJob, self).result(timeout=timeout, **kwargs)
  File "/home/airflow/.local/lib/python3.8/site-packages/google/api_core/future/polling.py", line 261, in result
    raise self._exception
google.api_core.exceptions.BadRequest: 400 No schema specified on job or table.
[2023-11-22T23:20:25.932+0000] {taskinstance.py:1400} INFO - Marking task as UP_FOR_RETRY. dag_id=outcomes_dag, task_id=Load_to_staging, execution_date=20231108T000000, start_date=20231122T232025, end_date=20231122T232025
[2023-11-22T23:20:25.952+0000] {standard_task_runner.py:104} ERROR - Failed to execute job 45 for task Load_to_staging (400 No schema specified on job or table.; 196)
[2023-11-22T23:20:25.978+0000] {local_task_job_runner.py:228} INFO - Task exited with return code 1
[2023-11-22T23:43:10.923+0000] {taskinstance.py:1159} INFO - Dependencies all met for dep_context=non-requeueable deps ti=<TaskInstance: outcomes_dag.Load_to_staging scheduled__2023-11-08T00:00:00+00:00 [queued]>
[2023-11-22T23:43:10.954+0000] {taskinstance.py:1159} INFO - Dependencies all met for dep_context=requeueable deps ti=<TaskInstance: outcomes_dag.Load_to_staging scheduled__2023-11-08T00:00:00+00:00 [queued]>
[2023-11-22T23:43:10.970+0000] {taskinstance.py:1361} INFO - Starting attempt 1 of 4
[2023-11-22T23:43:11.017+0000] {taskinstance.py:1382} INFO - Executing <Task(PythonOperator): Load_to_staging> on 2023-11-08 00:00:00+00:00
[2023-11-22T23:43:11.063+0000] {standard_task_runner.py:57} INFO - Started process 197 to run task
[2023-11-22T23:43:11.083+0000] {standard_task_runner.py:84} INFO - Running: ['***', 'tasks', 'run', 'outcomes_dag', 'Load_to_staging', 'scheduled__2023-11-08T00:00:00+00:00', '--job-id', '39', '--raw', '--subdir', 'DAGS_FOLDER/outcomes_dag.py', '--cfg-path', '/tmp/tmp2twe4ot0']
[2023-11-22T23:43:11.088+0000] {standard_task_runner.py:85} INFO - Job 39: Subtask Load_to_staging
[2023-11-22T23:43:11.679+0000] {task_command.py:416} INFO - Running <TaskInstance: outcomes_dag.Load_to_staging scheduled__2023-11-08T00:00:00+00:00 [running]> on host 371cae71aa63
[2023-11-22T23:43:12.230+0000] {taskinstance.py:1662} INFO - Exporting env vars: AIRFLOW_CTX_DAG_OWNER='***' AIRFLOW_CTX_DAG_ID='outcomes_dag' AIRFLOW_CTX_TASK_ID='Load_to_staging' AIRFLOW_CTX_EXECUTION_DATE='2023-11-08T00:00:00+00:00' AIRFLOW_CTX_TRY_NUMBER='1' AIRFLOW_CTX_DAG_RUN_ID='scheduled__2023-11-08T00:00:00+00:00'
[2023-11-22T23:43:12.677+0000] {taskinstance.py:1937} ERROR - Task failed with exception
Traceback (most recent call last):
  File "/home/airflow/.local/lib/python3.8/site-packages/airflow/operators/python.py", line 192, in execute
    return_value = self.execute_callable()
  File "/home/airflow/.local/lib/python3.8/site-packages/airflow/operators/python.py", line 209, in execute_callable
    return self.python_callable(*self.op_args, **self.op_kwargs)
  File "/opt/airflow/dags/ETL/load.py", line 33, in data_to_staging
    load_job.result()  # Wait for the job to complete
  File "/home/airflow/.local/lib/python3.8/site-packages/google/cloud/bigquery/job/base.py", line 922, in result
    return super(_AsyncJob, self).result(timeout=timeout, **kwargs)
  File "/home/airflow/.local/lib/python3.8/site-packages/google/api_core/future/polling.py", line 261, in result
    raise self._exception
google.api_core.exceptions.BadRequest: 400 No schema specified on job or table.
[2023-11-22T23:43:12.991+0000] {taskinstance.py:1400} INFO - Marking task as UP_FOR_RETRY. dag_id=outcomes_dag, task_id=Load_to_staging, execution_date=20231108T000000, start_date=20231122T234310, end_date=20231122T234312
[2023-11-22T23:43:13.199+0000] {standard_task_runner.py:104} ERROR - Failed to execute job 39 for task Load_to_staging (400 No schema specified on job or table.; 197)
[2023-11-22T23:43:13.453+0000] {local_task_job_runner.py:228} INFO - Task exited with return code 1
[2023-11-23T00:39:44.787+0000] {taskinstance.py:1159} INFO - Dependencies all met for dep_context=non-requeueable deps ti=<TaskInstance: outcomes_dag.Load_to_staging scheduled__2023-11-08T00:00:00+00:00 [queued]>
[2023-11-23T00:39:44.814+0000] {taskinstance.py:1159} INFO - Dependencies all met for dep_context=requeueable deps ti=<TaskInstance: outcomes_dag.Load_to_staging scheduled__2023-11-08T00:00:00+00:00 [queued]>
[2023-11-23T00:39:44.822+0000] {taskinstance.py:1361} INFO - Starting attempt 1 of 4
[2023-11-23T00:39:44.905+0000] {taskinstance.py:1382} INFO - Executing <Task(PythonOperator): Load_to_staging> on 2023-11-08 00:00:00+00:00
[2023-11-23T00:39:44.955+0000] {standard_task_runner.py:57} INFO - Started process 259 to run task
[2023-11-23T00:39:45.006+0000] {standard_task_runner.py:84} INFO - Running: ['***', 'tasks', 'run', 'outcomes_dag', 'Load_to_staging', 'scheduled__2023-11-08T00:00:00+00:00', '--job-id', '59', '--raw', '--subdir', 'DAGS_FOLDER/outcomes_dag.py', '--cfg-path', '/tmp/tmp6ha9tn1u']
[2023-11-23T00:39:45.033+0000] {standard_task_runner.py:85} INFO - Job 59: Subtask Load_to_staging
[2023-11-23T00:39:45.383+0000] {task_command.py:416} INFO - Running <TaskInstance: outcomes_dag.Load_to_staging scheduled__2023-11-08T00:00:00+00:00 [running]> on host 75913536581a
[2023-11-23T00:39:45.701+0000] {taskinstance.py:1662} INFO - Exporting env vars: AIRFLOW_CTX_DAG_OWNER='***' AIRFLOW_CTX_DAG_ID='outcomes_dag' AIRFLOW_CTX_TASK_ID='Load_to_staging' AIRFLOW_CTX_EXECUTION_DATE='2023-11-08T00:00:00+00:00' AIRFLOW_CTX_TRY_NUMBER='1' AIRFLOW_CTX_DAG_RUN_ID='scheduled__2023-11-08T00:00:00+00:00'
[2023-11-23T00:39:46.383+0000] {taskinstance.py:1937} ERROR - Task failed with exception
Traceback (most recent call last):
  File "/home/airflow/.local/lib/python3.8/site-packages/airflow/operators/python.py", line 192, in execute
    return_value = self.execute_callable()
  File "/home/airflow/.local/lib/python3.8/site-packages/airflow/operators/python.py", line 209, in execute_callable
    return self.python_callable(*self.op_args, **self.op_kwargs)
  File "/opt/airflow/dags/ETL/load.py", line 33, in data_to_staging
    load_job = client.load_table_from_uri(uri, table_ref, job_config=job_config)
  File "/home/airflow/.local/lib/python3.8/site-packages/google/cloud/bigquery/client.py", line 2375, in load_table_from_uri
    load_job._begin(retry=retry, timeout=timeout)
  File "/home/airflow/.local/lib/python3.8/site-packages/google/cloud/bigquery/job/base.py", line 693, in _begin
    api_response = client._call_api(
  File "/home/airflow/.local/lib/python3.8/site-packages/google/cloud/bigquery/client.py", line 808, in _call_api
    return call()
  File "/home/airflow/.local/lib/python3.8/site-packages/google/api_core/retry.py", line 366, in retry_wrapped_func
    return retry_target(
  File "/home/airflow/.local/lib/python3.8/site-packages/google/api_core/retry.py", line 204, in retry_target
    return target()
  File "/home/airflow/.local/lib/python3.8/site-packages/google/cloud/_http/__init__.py", line 494, in api_request
    raise exceptions.from_http_response(response)
google.api_core.exceptions.NotFound: 404 POST https://bigquery.googleapis.com/bigquery/v2/projects/dcsc-warehouse/jobs?prettyPrint=false: Not found: Dataset dcsc-warehouse:dcsc-warehouse.shelter_warehouse_schema
[2023-11-23T00:39:46.457+0000] {taskinstance.py:1400} INFO - Marking task as UP_FOR_RETRY. dag_id=outcomes_dag, task_id=Load_to_staging, execution_date=20231108T000000, start_date=20231123T003944, end_date=20231123T003946
[2023-11-23T00:39:46.493+0000] {standard_task_runner.py:104} ERROR - Failed to execute job 59 for task Load_to_staging (404 POST https://bigquery.googleapis.com/bigquery/v2/projects/dcsc-warehouse/jobs?prettyPrint=false: Not found: Dataset dcsc-warehouse:dcsc-warehouse.shelter_warehouse_schema; 259)
[2023-11-23T00:39:46.642+0000] {local_task_job_runner.py:228} INFO - Task exited with return code 1
