[2023-11-22T23:12:57.776+0000] {taskinstance.py:1159} INFO - Dependencies all met for dep_context=non-requeueable deps ti=<TaskInstance: outcomes_dag.Load_to_staging scheduled__2023-11-21T00:00:00+00:00 [queued]>
[2023-11-22T23:12:57.781+0000] {taskinstance.py:1159} INFO - Dependencies all met for dep_context=requeueable deps ti=<TaskInstance: outcomes_dag.Load_to_staging scheduled__2023-11-21T00:00:00+00:00 [queued]>
[2023-11-22T23:12:57.781+0000] {taskinstance.py:1361} INFO - Starting attempt 8 of 8
[2023-11-22T23:12:57.788+0000] {taskinstance.py:1382} INFO - Executing <Task(PythonOperator): Load_to_staging> on 2023-11-21 00:00:00+00:00
[2023-11-22T23:12:57.793+0000] {standard_task_runner.py:57} INFO - Started process 736 to run task
[2023-11-22T23:12:57.796+0000] {standard_task_runner.py:84} INFO - Running: ['***', 'tasks', 'run', 'outcomes_dag', 'Load_to_staging', 'scheduled__2023-11-21T00:00:00+00:00', '--job-id', '161', '--raw', '--subdir', 'DAGS_FOLDER/outcomes_dag.py', '--cfg-path', '/tmp/tmpo6ui8pyh']
[2023-11-22T23:12:57.800+0000] {standard_task_runner.py:85} INFO - Job 161: Subtask Load_to_staging
[2023-11-22T23:12:57.835+0000] {task_command.py:416} INFO - Running <TaskInstance: outcomes_dag.Load_to_staging scheduled__2023-11-21T00:00:00+00:00 [running]> on host 4b2f5af281f8
[2023-11-22T23:12:57.882+0000] {taskinstance.py:1662} INFO - Exporting env vars: AIRFLOW_CTX_DAG_OWNER='***' AIRFLOW_CTX_DAG_ID='outcomes_dag' AIRFLOW_CTX_TASK_ID='Load_to_staging' AIRFLOW_CTX_EXECUTION_DATE='2023-11-21T00:00:00+00:00' AIRFLOW_CTX_TRY_NUMBER='8' AIRFLOW_CTX_DAG_RUN_ID='scheduled__2023-11-21T00:00:00+00:00'
[2023-11-22T23:12:59.342+0000] {taskinstance.py:1937} ERROR - Task failed with exception
Traceback (most recent call last):
  File "/home/airflow/.local/lib/python3.8/site-packages/airflow/operators/python.py", line 192, in execute
    return_value = self.execute_callable()
  File "/home/airflow/.local/lib/python3.8/site-packages/airflow/operators/python.py", line 209, in execute_callable
    return self.python_callable(*self.op_args, **self.op_kwargs)
  File "/opt/airflow/dags/ETL/load.py", line 33, in data_to_staging
    load_job.result()  # Wait for the job to complete
  File "/home/airflow/.local/lib/python3.8/site-packages/google/cloud/bigquery/job/base.py", line 922, in result
    return super(_AsyncJob, self).result(timeout=timeout, **kwargs)
  File "/home/airflow/.local/lib/python3.8/site-packages/google/api_core/future/polling.py", line 261, in result
    raise self._exception
google.api_core.exceptions.BadRequest: 400 No schema specified on job or table.
[2023-11-22T23:12:59.361+0000] {taskinstance.py:1400} INFO - Marking task as FAILED. dag_id=outcomes_dag, task_id=Load_to_staging, execution_date=20231121T000000, start_date=20231122T231257, end_date=20231122T231259
[2023-11-22T23:12:59.373+0000] {standard_task_runner.py:104} ERROR - Failed to execute job 161 for task Load_to_staging (400 No schema specified on job or table.; 736)
[2023-11-22T23:12:59.395+0000] {local_task_job_runner.py:228} INFO - Task exited with return code 1
[2023-11-22T23:58:13.622+0000] {taskinstance.py:1159} INFO - Dependencies all met for dep_context=non-requeueable deps ti=<TaskInstance: outcomes_dag.Load_to_staging scheduled__2023-11-21T00:00:00+00:00 [queued]>
[2023-11-22T23:58:13.626+0000] {taskinstance.py:1159} INFO - Dependencies all met for dep_context=requeueable deps ti=<TaskInstance: outcomes_dag.Load_to_staging scheduled__2023-11-21T00:00:00+00:00 [queued]>
[2023-11-22T23:58:13.627+0000] {taskinstance.py:1361} INFO - Starting attempt 8 of 8
[2023-11-22T23:58:13.637+0000] {taskinstance.py:1382} INFO - Executing <Task(PythonOperator): Load_to_staging> on 2023-11-21 00:00:00+00:00
[2023-11-22T23:58:13.649+0000] {standard_task_runner.py:57} INFO - Started process 735 to run task
[2023-11-22T23:58:13.652+0000] {standard_task_runner.py:84} INFO - Running: ['***', 'tasks', 'run', 'outcomes_dag', 'Load_to_staging', 'scheduled__2023-11-21T00:00:00+00:00', '--job-id', '150', '--raw', '--subdir', 'DAGS_FOLDER/outcomes_dag.py', '--cfg-path', '/tmp/tmp9djxo09q']
[2023-11-22T23:58:13.659+0000] {standard_task_runner.py:85} INFO - Job 150: Subtask Load_to_staging
[2023-11-22T23:58:13.703+0000] {task_command.py:416} INFO - Running <TaskInstance: outcomes_dag.Load_to_staging scheduled__2023-11-21T00:00:00+00:00 [running]> on host 371cae71aa63
[2023-11-22T23:58:13.751+0000] {taskinstance.py:1662} INFO - Exporting env vars: AIRFLOW_CTX_DAG_OWNER='***' AIRFLOW_CTX_DAG_ID='outcomes_dag' AIRFLOW_CTX_TASK_ID='Load_to_staging' AIRFLOW_CTX_EXECUTION_DATE='2023-11-21T00:00:00+00:00' AIRFLOW_CTX_TRY_NUMBER='8' AIRFLOW_CTX_DAG_RUN_ID='scheduled__2023-11-21T00:00:00+00:00'
[2023-11-22T23:58:14.161+0000] {taskinstance.py:1937} ERROR - Task failed with exception
Traceback (most recent call last):
  File "/home/airflow/.local/lib/python3.8/site-packages/airflow/operators/python.py", line 192, in execute
    return_value = self.execute_callable()
  File "/home/airflow/.local/lib/python3.8/site-packages/airflow/operators/python.py", line 209, in execute_callable
    return self.python_callable(*self.op_args, **self.op_kwargs)
  File "/opt/airflow/dags/ETL/load.py", line 33, in data_to_staging
    load_job.result()  # Wait for the job to complete
  File "/home/airflow/.local/lib/python3.8/site-packages/google/cloud/bigquery/job/base.py", line 922, in result
    return super(_AsyncJob, self).result(timeout=timeout, **kwargs)
  File "/home/airflow/.local/lib/python3.8/site-packages/google/api_core/future/polling.py", line 261, in result
    raise self._exception
google.api_core.exceptions.BadRequest: 400 No schema specified on job or table.
[2023-11-22T23:58:14.177+0000] {taskinstance.py:1400} INFO - Marking task as FAILED. dag_id=outcomes_dag, task_id=Load_to_staging, execution_date=20231121T000000, start_date=20231122T235813, end_date=20231122T235814
[2023-11-22T23:58:14.184+0000] {standard_task_runner.py:104} ERROR - Failed to execute job 150 for task Load_to_staging (400 No schema specified on job or table.; 735)
[2023-11-22T23:58:14.199+0000] {local_task_job_runner.py:228} INFO - Task exited with return code 1
