[2023-11-22T23:03:12.791+0000] {taskinstance.py:1159} INFO - Dependencies all met for dep_context=non-requeueable deps ti=<TaskInstance: outcomes_dag.Load_to_staging scheduled__2023-11-04T00:00:00+00:00 [queued]>
[2023-11-22T23:03:12.807+0000] {taskinstance.py:1159} INFO - Dependencies all met for dep_context=requeueable deps ti=<TaskInstance: outcomes_dag.Load_to_staging scheduled__2023-11-04T00:00:00+00:00 [queued]>
[2023-11-22T23:03:12.808+0000] {taskinstance.py:1361} INFO - Starting attempt 4 of 4
[2023-11-22T23:03:12.828+0000] {taskinstance.py:1382} INFO - Executing <Task(PythonOperator): Load_to_staging> on 2023-11-04 00:00:00+00:00
[2023-11-22T23:03:12.839+0000] {standard_task_runner.py:57} INFO - Started process 420 to run task
[2023-11-22T23:03:12.845+0000] {standard_task_runner.py:84} INFO - Running: ['***', 'tasks', 'run', 'outcomes_dag', 'Load_to_staging', 'scheduled__2023-11-04T00:00:00+00:00', '--job-id', '103', '--raw', '--subdir', 'DAGS_FOLDER/outcomes_dag.py', '--cfg-path', '/tmp/tmpx1a8upqg']
[2023-11-22T23:03:12.851+0000] {standard_task_runner.py:85} INFO - Job 103: Subtask Load_to_staging
[2023-11-22T23:03:12.939+0000] {task_command.py:416} INFO - Running <TaskInstance: outcomes_dag.Load_to_staging scheduled__2023-11-04T00:00:00+00:00 [running]> on host 4b2f5af281f8
[2023-11-22T23:03:13.024+0000] {taskinstance.py:1662} INFO - Exporting env vars: AIRFLOW_CTX_DAG_OWNER='***' AIRFLOW_CTX_DAG_ID='outcomes_dag' AIRFLOW_CTX_TASK_ID='Load_to_staging' AIRFLOW_CTX_EXECUTION_DATE='2023-11-04T00:00:00+00:00' AIRFLOW_CTX_TRY_NUMBER='4' AIRFLOW_CTX_DAG_RUN_ID='scheduled__2023-11-04T00:00:00+00:00'
[2023-11-22T23:03:13.398+0000] {taskinstance.py:1937} ERROR - Task failed with exception
Traceback (most recent call last):
  File "/home/airflow/.local/lib/python3.8/site-packages/airflow/operators/python.py", line 192, in execute
    return_value = self.execute_callable()
  File "/home/airflow/.local/lib/python3.8/site-packages/airflow/operators/python.py", line 209, in execute_callable
    return self.python_callable(*self.op_args, **self.op_kwargs)
  File "/opt/airflow/dags/ETL/load.py", line 31, in data_to_staging
    load_job = client.load_table_from_uri(uri, table_ref, job_config=job_config)
  File "/home/airflow/.local/lib/python3.8/site-packages/google/cloud/bigquery/client.py", line 2375, in load_table_from_uri
    load_job._begin(retry=retry, timeout=timeout)
  File "/home/airflow/.local/lib/python3.8/site-packages/google/cloud/bigquery/job/base.py", line 693, in _begin
    api_response = client._call_api(
  File "/home/airflow/.local/lib/python3.8/site-packages/google/cloud/bigquery/client.py", line 808, in _call_api
    return call()
  File "/home/airflow/.local/lib/python3.8/site-packages/google/api_core/retry.py", line 366, in retry_wrapped_func
    return retry_target(
  File "/home/airflow/.local/lib/python3.8/site-packages/google/api_core/retry.py", line 204, in retry_target
    return target()
  File "/home/airflow/.local/lib/python3.8/site-packages/google/cloud/_http/__init__.py", line 494, in api_request
    raise exceptions.from_http_response(response)
google.api_core.exceptions.NotFound: 404 POST https://bigquery.googleapis.com/bigquery/v2/projects/dcsc-warehouse/jobs?prettyPrint=false: Not found: Dataset dcsc-warehouse:dcsc-warehouse.shelter_warehouse_schema
[2023-11-22T23:03:13.413+0000] {taskinstance.py:1400} INFO - Marking task as FAILED. dag_id=outcomes_dag, task_id=Load_to_staging, execution_date=20231104T000000, start_date=20231122T230312, end_date=20231122T230313
[2023-11-22T23:03:13.430+0000] {standard_task_runner.py:104} ERROR - Failed to execute job 103 for task Load_to_staging (404 POST https://bigquery.googleapis.com/bigquery/v2/projects/dcsc-warehouse/jobs?prettyPrint=false: Not found: Dataset dcsc-warehouse:dcsc-warehouse.shelter_warehouse_schema; 420)
[2023-11-22T23:03:13.463+0000] {local_task_job_runner.py:228} INFO - Task exited with return code 1
[2023-11-22T23:23:42.089+0000] {taskinstance.py:1159} INFO - Dependencies all met for dep_context=non-requeueable deps ti=<TaskInstance: outcomes_dag.Load_to_staging scheduled__2023-11-04T00:00:00+00:00 [queued]>
[2023-11-22T23:23:42.097+0000] {taskinstance.py:1159} INFO - Dependencies all met for dep_context=requeueable deps ti=<TaskInstance: outcomes_dag.Load_to_staging scheduled__2023-11-04T00:00:00+00:00 [queued]>
[2023-11-22T23:23:42.097+0000] {taskinstance.py:1361} INFO - Starting attempt 4 of 4
[2023-11-22T23:23:42.124+0000] {taskinstance.py:1382} INFO - Executing <Task(PythonOperator): Load_to_staging> on 2023-11-04 00:00:00+00:00
[2023-11-22T23:23:42.148+0000] {standard_task_runner.py:57} INFO - Started process 399 to run task
[2023-11-22T23:23:42.172+0000] {standard_task_runner.py:84} INFO - Running: ['***', 'tasks', 'run', 'outcomes_dag', 'Load_to_staging', 'scheduled__2023-11-04T00:00:00+00:00', '--job-id', '88', '--raw', '--subdir', 'DAGS_FOLDER/outcomes_dag.py', '--cfg-path', '/tmp/tmpn3xn8n5h']
[2023-11-22T23:23:42.202+0000] {standard_task_runner.py:85} INFO - Job 88: Subtask Load_to_staging
[2023-11-22T23:23:42.354+0000] {task_command.py:416} INFO - Running <TaskInstance: outcomes_dag.Load_to_staging scheduled__2023-11-04T00:00:00+00:00 [running]> on host b410bfb4af5e
[2023-11-22T23:23:42.526+0000] {taskinstance.py:1662} INFO - Exporting env vars: AIRFLOW_CTX_DAG_OWNER='***' AIRFLOW_CTX_DAG_ID='outcomes_dag' AIRFLOW_CTX_TASK_ID='Load_to_staging' AIRFLOW_CTX_EXECUTION_DATE='2023-11-04T00:00:00+00:00' AIRFLOW_CTX_TRY_NUMBER='4' AIRFLOW_CTX_DAG_RUN_ID='scheduled__2023-11-04T00:00:00+00:00'
[2023-11-22T23:23:42.771+0000] {taskinstance.py:1937} ERROR - Task failed with exception
Traceback (most recent call last):
  File "/home/airflow/.local/lib/python3.8/site-packages/airflow/operators/python.py", line 192, in execute
    return_value = self.execute_callable()
  File "/home/airflow/.local/lib/python3.8/site-packages/airflow/operators/python.py", line 209, in execute_callable
    return self.python_callable(*self.op_args, **self.op_kwargs)
  File "/opt/airflow/dags/ETL/load.py", line 33, in data_to_staging
    load_job.result()  # Wait for the job to complete
  File "/home/airflow/.local/lib/python3.8/site-packages/google/cloud/bigquery/job/base.py", line 922, in result
    return super(_AsyncJob, self).result(timeout=timeout, **kwargs)
  File "/home/airflow/.local/lib/python3.8/site-packages/google/api_core/future/polling.py", line 261, in result
    raise self._exception
google.api_core.exceptions.BadRequest: 400 No schema specified on job or table.
[2023-11-22T23:23:42.808+0000] {taskinstance.py:1400} INFO - Marking task as FAILED. dag_id=outcomes_dag, task_id=Load_to_staging, execution_date=20231104T000000, start_date=20231122T232342, end_date=20231122T232342
[2023-11-22T23:23:42.857+0000] {standard_task_runner.py:104} ERROR - Failed to execute job 88 for task Load_to_staging (400 No schema specified on job or table.; 399)
[2023-11-22T23:23:42.960+0000] {local_task_job_runner.py:228} INFO - Task exited with return code 1
[2023-11-22T23:46:20.305+0000] {taskinstance.py:1159} INFO - Dependencies all met for dep_context=non-requeueable deps ti=<TaskInstance: outcomes_dag.Load_to_staging scheduled__2023-11-04T00:00:00+00:00 [queued]>
[2023-11-22T23:46:20.310+0000] {taskinstance.py:1159} INFO - Dependencies all met for dep_context=requeueable deps ti=<TaskInstance: outcomes_dag.Load_to_staging scheduled__2023-11-04T00:00:00+00:00 [queued]>
[2023-11-22T23:46:20.310+0000] {taskinstance.py:1361} INFO - Starting attempt 4 of 4
[2023-11-22T23:46:20.316+0000] {taskinstance.py:1382} INFO - Executing <Task(PythonOperator): Load_to_staging> on 2023-11-04 00:00:00+00:00
[2023-11-22T23:46:20.323+0000] {standard_task_runner.py:57} INFO - Started process 361 to run task
[2023-11-22T23:46:20.326+0000] {standard_task_runner.py:84} INFO - Running: ['***', 'tasks', 'run', 'outcomes_dag', 'Load_to_staging', 'scheduled__2023-11-04T00:00:00+00:00', '--job-id', '83', '--raw', '--subdir', 'DAGS_FOLDER/outcomes_dag.py', '--cfg-path', '/tmp/tmpn3m6dhci']
[2023-11-22T23:46:20.328+0000] {standard_task_runner.py:85} INFO - Job 83: Subtask Load_to_staging
[2023-11-22T23:46:20.369+0000] {task_command.py:416} INFO - Running <TaskInstance: outcomes_dag.Load_to_staging scheduled__2023-11-04T00:00:00+00:00 [running]> on host 371cae71aa63
[2023-11-22T23:46:20.422+0000] {taskinstance.py:1662} INFO - Exporting env vars: AIRFLOW_CTX_DAG_OWNER='***' AIRFLOW_CTX_DAG_ID='outcomes_dag' AIRFLOW_CTX_TASK_ID='Load_to_staging' AIRFLOW_CTX_EXECUTION_DATE='2023-11-04T00:00:00+00:00' AIRFLOW_CTX_TRY_NUMBER='4' AIRFLOW_CTX_DAG_RUN_ID='scheduled__2023-11-04T00:00:00+00:00'
[2023-11-22T23:46:20.714+0000] {taskinstance.py:1937} ERROR - Task failed with exception
Traceback (most recent call last):
  File "/home/airflow/.local/lib/python3.8/site-packages/airflow/operators/python.py", line 192, in execute
    return_value = self.execute_callable()
  File "/home/airflow/.local/lib/python3.8/site-packages/airflow/operators/python.py", line 209, in execute_callable
    return self.python_callable(*self.op_args, **self.op_kwargs)
  File "/opt/airflow/dags/ETL/load.py", line 33, in data_to_staging
    load_job.result()  # Wait for the job to complete
  File "/home/airflow/.local/lib/python3.8/site-packages/google/cloud/bigquery/job/base.py", line 922, in result
    return super(_AsyncJob, self).result(timeout=timeout, **kwargs)
  File "/home/airflow/.local/lib/python3.8/site-packages/google/api_core/future/polling.py", line 261, in result
    raise self._exception
google.api_core.exceptions.BadRequest: 400 No schema specified on job or table.
[2023-11-22T23:46:20.730+0000] {taskinstance.py:1400} INFO - Marking task as FAILED. dag_id=outcomes_dag, task_id=Load_to_staging, execution_date=20231104T000000, start_date=20231122T234620, end_date=20231122T234620
[2023-11-22T23:46:20.738+0000] {standard_task_runner.py:104} ERROR - Failed to execute job 83 for task Load_to_staging (400 No schema specified on job or table.; 361)
[2023-11-22T23:46:20.748+0000] {local_task_job_runner.py:228} INFO - Task exited with return code 1
[2023-11-23T00:42:49.069+0000] {taskinstance.py:1159} INFO - Dependencies all met for dep_context=non-requeueable deps ti=<TaskInstance: outcomes_dag.Load_to_staging scheduled__2023-11-04T00:00:00+00:00 [queued]>
[2023-11-23T00:42:49.073+0000] {taskinstance.py:1159} INFO - Dependencies all met for dep_context=requeueable deps ti=<TaskInstance: outcomes_dag.Load_to_staging scheduled__2023-11-04T00:00:00+00:00 [queued]>
[2023-11-23T00:42:49.073+0000] {taskinstance.py:1361} INFO - Starting attempt 4 of 4
[2023-11-23T00:42:49.079+0000] {taskinstance.py:1382} INFO - Executing <Task(PythonOperator): Load_to_staging> on 2023-11-04 00:00:00+00:00
[2023-11-23T00:42:49.086+0000] {standard_task_runner.py:57} INFO - Started process 403 to run task
[2023-11-23T00:42:49.089+0000] {standard_task_runner.py:84} INFO - Running: ['***', 'tasks', 'run', 'outcomes_dag', 'Load_to_staging', 'scheduled__2023-11-04T00:00:00+00:00', '--job-id', '99', '--raw', '--subdir', 'DAGS_FOLDER/outcomes_dag.py', '--cfg-path', '/tmp/tmp_thrg3i3']
[2023-11-23T00:42:49.092+0000] {standard_task_runner.py:85} INFO - Job 99: Subtask Load_to_staging
[2023-11-23T00:42:49.131+0000] {task_command.py:416} INFO - Running <TaskInstance: outcomes_dag.Load_to_staging scheduled__2023-11-04T00:00:00+00:00 [running]> on host 75913536581a
[2023-11-23T00:42:49.177+0000] {taskinstance.py:1662} INFO - Exporting env vars: AIRFLOW_CTX_DAG_OWNER='***' AIRFLOW_CTX_DAG_ID='outcomes_dag' AIRFLOW_CTX_TASK_ID='Load_to_staging' AIRFLOW_CTX_EXECUTION_DATE='2023-11-04T00:00:00+00:00' AIRFLOW_CTX_TRY_NUMBER='4' AIRFLOW_CTX_DAG_RUN_ID='scheduled__2023-11-04T00:00:00+00:00'
[2023-11-23T00:42:50.320+0000] {taskinstance.py:1937} ERROR - Task failed with exception
Traceback (most recent call last):
  File "/home/airflow/.local/lib/python3.8/site-packages/airflow/operators/python.py", line 192, in execute
    return_value = self.execute_callable()
  File "/home/airflow/.local/lib/python3.8/site-packages/airflow/operators/python.py", line 209, in execute_callable
    return self.python_callable(*self.op_args, **self.op_kwargs)
  File "/opt/airflow/dags/ETL/load.py", line 33, in data_to_staging
    load_job = client.load_table_from_uri(uri, table_ref, job_config=job_config)
  File "/home/airflow/.local/lib/python3.8/site-packages/google/cloud/bigquery/client.py", line 2375, in load_table_from_uri
    load_job._begin(retry=retry, timeout=timeout)
  File "/home/airflow/.local/lib/python3.8/site-packages/google/cloud/bigquery/job/base.py", line 693, in _begin
    api_response = client._call_api(
  File "/home/airflow/.local/lib/python3.8/site-packages/google/cloud/bigquery/client.py", line 808, in _call_api
    return call()
  File "/home/airflow/.local/lib/python3.8/site-packages/google/api_core/retry.py", line 366, in retry_wrapped_func
    return retry_target(
  File "/home/airflow/.local/lib/python3.8/site-packages/google/api_core/retry.py", line 204, in retry_target
    return target()
  File "/home/airflow/.local/lib/python3.8/site-packages/google/cloud/_http/__init__.py", line 494, in api_request
    raise exceptions.from_http_response(response)
google.api_core.exceptions.NotFound: 404 POST https://bigquery.googleapis.com/bigquery/v2/projects/dcsc-warehouse/jobs?prettyPrint=false: Not found: Dataset dcsc-warehouse:dcsc-warehouse.shelter_warehouse_schema
[2023-11-23T00:42:50.377+0000] {taskinstance.py:1400} INFO - Marking task as FAILED. dag_id=outcomes_dag, task_id=Load_to_staging, execution_date=20231104T000000, start_date=20231123T004249, end_date=20231123T004250
[2023-11-23T00:42:50.406+0000] {standard_task_runner.py:104} ERROR - Failed to execute job 99 for task Load_to_staging (404 POST https://bigquery.googleapis.com/bigquery/v2/projects/dcsc-warehouse/jobs?prettyPrint=false: Not found: Dataset dcsc-warehouse:dcsc-warehouse.shelter_warehouse_schema; 403)
[2023-11-23T00:42:50.463+0000] {local_task_job_runner.py:228} INFO - Task exited with return code 1
