[2023-11-22T23:02:09.428+0000] {taskinstance.py:1159} INFO - Dependencies all met for dep_context=non-requeueable deps ti=<TaskInstance: outcomes_dag.Load_to_staging scheduled__2023-11-11T00:00:00+00:00 [queued]>
[2023-11-22T23:02:09.445+0000] {taskinstance.py:1159} INFO - Dependencies all met for dep_context=requeueable deps ti=<TaskInstance: outcomes_dag.Load_to_staging scheduled__2023-11-11T00:00:00+00:00 [queued]>
[2023-11-22T23:02:09.454+0000] {taskinstance.py:1361} INFO - Starting attempt 3 of 4
[2023-11-22T23:02:09.531+0000] {taskinstance.py:1382} INFO - Executing <Task(PythonOperator): Load_to_staging> on 2023-11-11 00:00:00+00:00
[2023-11-22T23:02:09.551+0000] {standard_task_runner.py:57} INFO - Started process 346 to run task
[2023-11-22T23:02:09.560+0000] {standard_task_runner.py:84} INFO - Running: ['***', 'tasks', 'run', 'outcomes_dag', 'Load_to_staging', 'scheduled__2023-11-11T00:00:00+00:00', '--job-id', '83', '--raw', '--subdir', 'DAGS_FOLDER/outcomes_dag.py', '--cfg-path', '/tmp/tmp4dzb9kj0']
[2023-11-22T23:02:09.570+0000] {standard_task_runner.py:85} INFO - Job 83: Subtask Load_to_staging
[2023-11-22T23:02:09.702+0000] {task_command.py:416} INFO - Running <TaskInstance: outcomes_dag.Load_to_staging scheduled__2023-11-11T00:00:00+00:00 [running]> on host 4b2f5af281f8
[2023-11-22T23:02:09.827+0000] {taskinstance.py:1662} INFO - Exporting env vars: AIRFLOW_CTX_DAG_OWNER='***' AIRFLOW_CTX_DAG_ID='outcomes_dag' AIRFLOW_CTX_TASK_ID='Load_to_staging' AIRFLOW_CTX_EXECUTION_DATE='2023-11-11T00:00:00+00:00' AIRFLOW_CTX_TRY_NUMBER='3' AIRFLOW_CTX_DAG_RUN_ID='scheduled__2023-11-11T00:00:00+00:00'
[2023-11-22T23:02:10.806+0000] {taskinstance.py:1937} ERROR - Task failed with exception
Traceback (most recent call last):
  File "/home/airflow/.local/lib/python3.8/site-packages/airflow/operators/python.py", line 192, in execute
    return_value = self.execute_callable()
  File "/home/airflow/.local/lib/python3.8/site-packages/airflow/operators/python.py", line 209, in execute_callable
    return self.python_callable(*self.op_args, **self.op_kwargs)
  File "/opt/airflow/dags/ETL/load.py", line 31, in data_to_staging
    load_job = client.load_table_from_uri(uri, table_ref, job_config=job_config)
  File "/home/airflow/.local/lib/python3.8/site-packages/google/cloud/bigquery/client.py", line 2375, in load_table_from_uri
    load_job._begin(retry=retry, timeout=timeout)
  File "/home/airflow/.local/lib/python3.8/site-packages/google/cloud/bigquery/job/base.py", line 693, in _begin
    api_response = client._call_api(
  File "/home/airflow/.local/lib/python3.8/site-packages/google/cloud/bigquery/client.py", line 808, in _call_api
    return call()
  File "/home/airflow/.local/lib/python3.8/site-packages/google/api_core/retry.py", line 366, in retry_wrapped_func
    return retry_target(
  File "/home/airflow/.local/lib/python3.8/site-packages/google/api_core/retry.py", line 204, in retry_target
    return target()
  File "/home/airflow/.local/lib/python3.8/site-packages/google/cloud/_http/__init__.py", line 494, in api_request
    raise exceptions.from_http_response(response)
google.api_core.exceptions.NotFound: 404 POST https://bigquery.googleapis.com/bigquery/v2/projects/dcsc-warehouse/jobs?prettyPrint=false: Not found: Dataset dcsc-warehouse:dcsc-warehouse.shelter_warehouse_schema
[2023-11-22T23:02:10.840+0000] {taskinstance.py:1400} INFO - Marking task as UP_FOR_RETRY. dag_id=outcomes_dag, task_id=Load_to_staging, execution_date=20231111T000000, start_date=20231122T230209, end_date=20231122T230210
[2023-11-22T23:02:10.858+0000] {standard_task_runner.py:104} ERROR - Failed to execute job 83 for task Load_to_staging (404 POST https://bigquery.googleapis.com/bigquery/v2/projects/dcsc-warehouse/jobs?prettyPrint=false: Not found: Dataset dcsc-warehouse:dcsc-warehouse.shelter_warehouse_schema; 346)
[2023-11-22T23:02:10.883+0000] {local_task_job_runner.py:228} INFO - Task exited with return code 1
[2023-11-22T23:22:33.216+0000] {taskinstance.py:1159} INFO - Dependencies all met for dep_context=non-requeueable deps ti=<TaskInstance: outcomes_dag.Load_to_staging scheduled__2023-11-11T00:00:00+00:00 [queued]>
[2023-11-22T23:22:33.224+0000] {taskinstance.py:1159} INFO - Dependencies all met for dep_context=requeueable deps ti=<TaskInstance: outcomes_dag.Load_to_staging scheduled__2023-11-11T00:00:00+00:00 [queued]>
[2023-11-22T23:22:33.229+0000] {taskinstance.py:1361} INFO - Starting attempt 3 of 4
[2023-11-22T23:22:33.255+0000] {taskinstance.py:1382} INFO - Executing <Task(PythonOperator): Load_to_staging> on 2023-11-11 00:00:00+00:00
[2023-11-22T23:22:33.261+0000] {standard_task_runner.py:57} INFO - Started process 299 to run task
[2023-11-22T23:22:33.280+0000] {standard_task_runner.py:84} INFO - Running: ['***', 'tasks', 'run', 'outcomes_dag', 'Load_to_staging', 'scheduled__2023-11-11T00:00:00+00:00', '--job-id', '69', '--raw', '--subdir', 'DAGS_FOLDER/outcomes_dag.py', '--cfg-path', '/tmp/tmpeg8gwtj3']
[2023-11-22T23:22:33.281+0000] {standard_task_runner.py:85} INFO - Job 69: Subtask Load_to_staging
[2023-11-22T23:22:33.437+0000] {task_command.py:416} INFO - Running <TaskInstance: outcomes_dag.Load_to_staging scheduled__2023-11-11T00:00:00+00:00 [running]> on host b410bfb4af5e
[2023-11-22T23:22:33.558+0000] {taskinstance.py:1662} INFO - Exporting env vars: AIRFLOW_CTX_DAG_OWNER='***' AIRFLOW_CTX_DAG_ID='outcomes_dag' AIRFLOW_CTX_TASK_ID='Load_to_staging' AIRFLOW_CTX_EXECUTION_DATE='2023-11-11T00:00:00+00:00' AIRFLOW_CTX_TRY_NUMBER='3' AIRFLOW_CTX_DAG_RUN_ID='scheduled__2023-11-11T00:00:00+00:00'
[2023-11-22T23:22:33.831+0000] {taskinstance.py:1937} ERROR - Task failed with exception
Traceback (most recent call last):
  File "/home/airflow/.local/lib/python3.8/site-packages/airflow/operators/python.py", line 192, in execute
    return_value = self.execute_callable()
  File "/home/airflow/.local/lib/python3.8/site-packages/airflow/operators/python.py", line 209, in execute_callable
    return self.python_callable(*self.op_args, **self.op_kwargs)
  File "/opt/airflow/dags/ETL/load.py", line 33, in data_to_staging
    load_job.result()  # Wait for the job to complete
  File "/home/airflow/.local/lib/python3.8/site-packages/google/cloud/bigquery/job/base.py", line 922, in result
    return super(_AsyncJob, self).result(timeout=timeout, **kwargs)
  File "/home/airflow/.local/lib/python3.8/site-packages/google/api_core/future/polling.py", line 261, in result
    raise self._exception
google.api_core.exceptions.BadRequest: 400 No schema specified on job or table.
[2023-11-22T23:22:33.849+0000] {taskinstance.py:1400} INFO - Marking task as UP_FOR_RETRY. dag_id=outcomes_dag, task_id=Load_to_staging, execution_date=20231111T000000, start_date=20231122T232233, end_date=20231122T232233
[2023-11-22T23:22:33.898+0000] {standard_task_runner.py:104} ERROR - Failed to execute job 69 for task Load_to_staging (400 No schema specified on job or table.; 299)
[2023-11-22T23:22:33.943+0000] {local_task_job_runner.py:228} INFO - Task exited with return code 1
[2023-11-22T23:45:26.002+0000] {taskinstance.py:1159} INFO - Dependencies all met for dep_context=non-requeueable deps ti=<TaskInstance: outcomes_dag.Load_to_staging scheduled__2023-11-11T00:00:00+00:00 [queued]>
[2023-11-22T23:45:26.021+0000] {taskinstance.py:1159} INFO - Dependencies all met for dep_context=requeueable deps ti=<TaskInstance: outcomes_dag.Load_to_staging scheduled__2023-11-11T00:00:00+00:00 [queued]>
[2023-11-22T23:45:26.022+0000] {taskinstance.py:1361} INFO - Starting attempt 3 of 4
[2023-11-22T23:45:26.046+0000] {taskinstance.py:1382} INFO - Executing <Task(PythonOperator): Load_to_staging> on 2023-11-11 00:00:00+00:00
[2023-11-22T23:45:26.086+0000] {standard_task_runner.py:57} INFO - Started process 329 to run task
[2023-11-22T23:45:26.099+0000] {standard_task_runner.py:84} INFO - Running: ['***', 'tasks', 'run', 'outcomes_dag', 'Load_to_staging', 'scheduled__2023-11-11T00:00:00+00:00', '--job-id', '75', '--raw', '--subdir', 'DAGS_FOLDER/outcomes_dag.py', '--cfg-path', '/tmp/tmpe432okcu']
[2023-11-22T23:45:26.105+0000] {standard_task_runner.py:85} INFO - Job 75: Subtask Load_to_staging
[2023-11-22T23:45:26.263+0000] {task_command.py:416} INFO - Running <TaskInstance: outcomes_dag.Load_to_staging scheduled__2023-11-11T00:00:00+00:00 [running]> on host 371cae71aa63
[2023-11-22T23:45:26.431+0000] {taskinstance.py:1662} INFO - Exporting env vars: AIRFLOW_CTX_DAG_OWNER='***' AIRFLOW_CTX_DAG_ID='outcomes_dag' AIRFLOW_CTX_TASK_ID='Load_to_staging' AIRFLOW_CTX_EXECUTION_DATE='2023-11-11T00:00:00+00:00' AIRFLOW_CTX_TRY_NUMBER='3' AIRFLOW_CTX_DAG_RUN_ID='scheduled__2023-11-11T00:00:00+00:00'
[2023-11-22T23:45:26.750+0000] {taskinstance.py:1937} ERROR - Task failed with exception
Traceback (most recent call last):
  File "/home/airflow/.local/lib/python3.8/site-packages/airflow/operators/python.py", line 192, in execute
    return_value = self.execute_callable()
  File "/home/airflow/.local/lib/python3.8/site-packages/airflow/operators/python.py", line 209, in execute_callable
    return self.python_callable(*self.op_args, **self.op_kwargs)
  File "/opt/airflow/dags/ETL/load.py", line 33, in data_to_staging
    load_job.result()  # Wait for the job to complete
  File "/home/airflow/.local/lib/python3.8/site-packages/google/cloud/bigquery/job/base.py", line 922, in result
    return super(_AsyncJob, self).result(timeout=timeout, **kwargs)
  File "/home/airflow/.local/lib/python3.8/site-packages/google/api_core/future/polling.py", line 261, in result
    raise self._exception
google.api_core.exceptions.BadRequest: 400 No schema specified on job or table.
[2023-11-22T23:45:26.772+0000] {taskinstance.py:1400} INFO - Marking task as UP_FOR_RETRY. dag_id=outcomes_dag, task_id=Load_to_staging, execution_date=20231111T000000, start_date=20231122T234526, end_date=20231122T234526
[2023-11-22T23:45:26.786+0000] {standard_task_runner.py:104} ERROR - Failed to execute job 75 for task Load_to_staging (400 No schema specified on job or table.; 329)
[2023-11-22T23:45:26.829+0000] {local_task_job_runner.py:228} INFO - Task exited with return code 1
[2023-11-23T00:41:56.019+0000] {taskinstance.py:1159} INFO - Dependencies all met for dep_context=non-requeueable deps ti=<TaskInstance: outcomes_dag.Load_to_staging scheduled__2023-11-11T00:00:00+00:00 [queued]>
[2023-11-23T00:41:56.076+0000] {taskinstance.py:1159} INFO - Dependencies all met for dep_context=requeueable deps ti=<TaskInstance: outcomes_dag.Load_to_staging scheduled__2023-11-11T00:00:00+00:00 [queued]>
[2023-11-23T00:41:56.077+0000] {taskinstance.py:1361} INFO - Starting attempt 3 of 4
[2023-11-23T00:41:56.159+0000] {taskinstance.py:1382} INFO - Executing <Task(PythonOperator): Load_to_staging> on 2023-11-11 00:00:00+00:00
[2023-11-23T00:41:56.220+0000] {standard_task_runner.py:57} INFO - Started process 382 to run task
[2023-11-23T00:41:56.280+0000] {standard_task_runner.py:84} INFO - Running: ['***', 'tasks', 'run', 'outcomes_dag', 'Load_to_staging', 'scheduled__2023-11-11T00:00:00+00:00', '--job-id', '88', '--raw', '--subdir', 'DAGS_FOLDER/outcomes_dag.py', '--cfg-path', '/tmp/tmp2gdg3sqa']
[2023-11-23T00:41:56.334+0000] {standard_task_runner.py:85} INFO - Job 88: Subtask Load_to_staging
[2023-11-23T00:41:56.620+0000] {task_command.py:416} INFO - Running <TaskInstance: outcomes_dag.Load_to_staging scheduled__2023-11-11T00:00:00+00:00 [running]> on host 75913536581a
[2023-11-23T00:41:56.972+0000] {taskinstance.py:1662} INFO - Exporting env vars: AIRFLOW_CTX_DAG_OWNER='***' AIRFLOW_CTX_DAG_ID='outcomes_dag' AIRFLOW_CTX_TASK_ID='Load_to_staging' AIRFLOW_CTX_EXECUTION_DATE='2023-11-11T00:00:00+00:00' AIRFLOW_CTX_TRY_NUMBER='3' AIRFLOW_CTX_DAG_RUN_ID='scheduled__2023-11-11T00:00:00+00:00'
[2023-11-23T00:41:57.992+0000] {taskinstance.py:1937} ERROR - Task failed with exception
Traceback (most recent call last):
  File "/home/airflow/.local/lib/python3.8/site-packages/airflow/operators/python.py", line 192, in execute
    return_value = self.execute_callable()
  File "/home/airflow/.local/lib/python3.8/site-packages/airflow/operators/python.py", line 209, in execute_callable
    return self.python_callable(*self.op_args, **self.op_kwargs)
  File "/opt/airflow/dags/ETL/load.py", line 33, in data_to_staging
    load_job = client.load_table_from_uri(uri, table_ref, job_config=job_config)
  File "/home/airflow/.local/lib/python3.8/site-packages/google/cloud/bigquery/client.py", line 2375, in load_table_from_uri
    load_job._begin(retry=retry, timeout=timeout)
  File "/home/airflow/.local/lib/python3.8/site-packages/google/cloud/bigquery/job/base.py", line 693, in _begin
    api_response = client._call_api(
  File "/home/airflow/.local/lib/python3.8/site-packages/google/cloud/bigquery/client.py", line 808, in _call_api
    return call()
  File "/home/airflow/.local/lib/python3.8/site-packages/google/api_core/retry.py", line 366, in retry_wrapped_func
    return retry_target(
  File "/home/airflow/.local/lib/python3.8/site-packages/google/api_core/retry.py", line 204, in retry_target
    return target()
  File "/home/airflow/.local/lib/python3.8/site-packages/google/cloud/_http/__init__.py", line 494, in api_request
    raise exceptions.from_http_response(response)
google.api_core.exceptions.NotFound: 404 POST https://bigquery.googleapis.com/bigquery/v2/projects/dcsc-warehouse/jobs?prettyPrint=false: Not found: Dataset dcsc-warehouse:dcsc-warehouse.shelter_warehouse_schema
[2023-11-23T00:41:58.152+0000] {taskinstance.py:1400} INFO - Marking task as UP_FOR_RETRY. dag_id=outcomes_dag, task_id=Load_to_staging, execution_date=20231111T000000, start_date=20231123T004156, end_date=20231123T004158
[2023-11-23T00:41:58.306+0000] {standard_task_runner.py:104} ERROR - Failed to execute job 88 for task Load_to_staging (404 POST https://bigquery.googleapis.com/bigquery/v2/projects/dcsc-warehouse/jobs?prettyPrint=false: Not found: Dataset dcsc-warehouse:dcsc-warehouse.shelter_warehouse_schema; 382)
[2023-11-23T00:41:58.415+0000] {local_task_job_runner.py:228} INFO - Task exited with return code 1
