[2023-11-23T03:30:03.146+0000] {taskinstance.py:1159} INFO - Dependencies all met for dep_context=non-requeueable deps ti=<TaskInstance: outcomes_dag.dim4_to_cloud scheduled__2023-11-22T00:00:00+00:00 [queued]>
[2023-11-23T03:30:03.154+0000] {taskinstance.py:1159} INFO - Dependencies all met for dep_context=requeueable deps ti=<TaskInstance: outcomes_dag.dim4_to_cloud scheduled__2023-11-22T00:00:00+00:00 [queued]>
[2023-11-23T03:30:03.154+0000] {taskinstance.py:1361} INFO - Starting attempt 3 of 3
[2023-11-23T03:30:03.163+0000] {taskinstance.py:1382} INFO - Executing <Task(PythonOperator): dim4_to_cloud> on 2023-11-22 00:00:00+00:00
[2023-11-23T03:30:03.171+0000] {standard_task_runner.py:57} INFO - Started process 720 to run task
[2023-11-23T03:30:03.178+0000] {standard_task_runner.py:84} INFO - Running: ['***', 'tasks', 'run', 'outcomes_dag', 'dim4_to_cloud', 'scheduled__2023-11-22T00:00:00+00:00', '--job-id', '51', '--raw', '--subdir', 'DAGS_FOLDER/outcomes_dag.py', '--cfg-path', '/tmp/tmp63p9d5pl']
[2023-11-23T03:30:03.187+0000] {standard_task_runner.py:85} INFO - Job 51: Subtask dim4_to_cloud
[2023-11-23T03:30:03.242+0000] {task_command.py:416} INFO - Running <TaskInstance: outcomes_dag.dim4_to_cloud scheduled__2023-11-22T00:00:00+00:00 [running]> on host 1268bd8e5db0
[2023-11-23T03:30:03.315+0000] {taskinstance.py:1662} INFO - Exporting env vars: AIRFLOW_CTX_DAG_OWNER='***' AIRFLOW_CTX_DAG_ID='outcomes_dag' AIRFLOW_CTX_TASK_ID='dim4_to_cloud' AIRFLOW_CTX_EXECUTION_DATE='2023-11-22T00:00:00+00:00' AIRFLOW_CTX_TRY_NUMBER='3' AIRFLOW_CTX_DAG_RUN_ID='scheduled__2023-11-22T00:00:00+00:00'
[2023-11-23T03:30:03.870+0000] {taskinstance.py:1937} ERROR - Task failed with exception
Traceback (most recent call last):
  File "/home/airflow/.local/lib/python3.8/site-packages/google/cloud/bigquery/client.py", line 2481, in load_table_from_file
    response = self._do_multipart_upload(
  File "/home/airflow/.local/lib/python3.8/site-packages/google/cloud/bigquery/client.py", line 3036, in _do_multipart_upload
    response = upload.transmit(
  File "/home/airflow/.local/lib/python3.8/site-packages/google/resumable_media/requests/upload.py", line 153, in transmit
    return _request_helpers.wait_and_retry(
  File "/home/airflow/.local/lib/python3.8/site-packages/google/resumable_media/requests/_request_helpers.py", line 155, in wait_and_retry
    response = func()
  File "/home/airflow/.local/lib/python3.8/site-packages/google/resumable_media/requests/upload.py", line 149, in retriable_request
    self._process_response(result)
  File "/home/airflow/.local/lib/python3.8/site-packages/google/resumable_media/_upload.py", line 125, in _process_response
    _helpers.require_status_code(response, (http.client.OK,), self._get_status_code)
  File "/home/airflow/.local/lib/python3.8/site-packages/google/resumable_media/_helpers.py", line 108, in require_status_code
    raise common.InvalidResponse(
google.resumable_media.common.InvalidResponse: ('Request failed with status code', 404, 'Expected one of', 200)

During handling of the above exception, another exception occurred:

Traceback (most recent call last):
  File "/home/airflow/.local/lib/python3.8/site-packages/airflow/operators/python.py", line 192, in execute
    return_value = self.execute_callable()
  File "/home/airflow/.local/lib/python3.8/site-packages/airflow/operators/python.py", line 209, in execute_callable
    return self.python_callable(*self.op_args, **self.op_kwargs)
  File "/opt/airflow/dags/ETL/load_to_Cloud.py", line 25, in transfer_data_to_bigquery
    client.load_table_from_dataframe(df, table_ref, job_config=job_config)
  File "/home/airflow/.local/lib/python3.8/site-packages/google/cloud/bigquery/client.py", line 2717, in load_table_from_dataframe
    return self.load_table_from_file(
  File "/home/airflow/.local/lib/python3.8/site-packages/google/cloud/bigquery/client.py", line 2485, in load_table_from_file
    raise exceptions.from_http_response(exc.response)
google.api_core.exceptions.NotFound: 404 POST https://bigquery.googleapis.com/upload/bigquery/v2/projects/dcsc-warehouse/jobs?uploadType=multipart: Not found: Dataset dcsc-warehouse:dcsc-warehouse.shelter_warehouse_schema
[2023-11-23T03:30:03.884+0000] {taskinstance.py:1400} INFO - Marking task as FAILED. dag_id=outcomes_dag, task_id=dim4_to_cloud, execution_date=20231122T000000, start_date=20231123T033003, end_date=20231123T033003
[2023-11-23T03:30:03.896+0000] {standard_task_runner.py:104} ERROR - Failed to execute job 51 for task dim4_to_cloud (404 POST https://bigquery.googleapis.com/upload/bigquery/v2/projects/dcsc-warehouse/jobs?uploadType=multipart: Not found: Dataset dcsc-warehouse:dcsc-warehouse.shelter_warehouse_schema; 720)
[2023-11-23T03:30:03.925+0000] {local_task_job_runner.py:228} INFO - Task exited with return code 1
