[2023-11-22T03:10:00.335+0000] {taskinstance.py:1159} INFO - Dependencies all met for dep_context=non-requeueable deps ti=<TaskInstance: outcomes_dag.Transform manual__2023-11-22T03:09:53.954584+00:00 [queued]>
[2023-11-22T03:10:00.338+0000] {taskinstance.py:1159} INFO - Dependencies all met for dep_context=requeueable deps ti=<TaskInstance: outcomes_dag.Transform manual__2023-11-22T03:09:53.954584+00:00 [queued]>
[2023-11-22T03:10:00.339+0000] {taskinstance.py:1361} INFO - Starting attempt 1 of 1
[2023-11-22T03:10:00.344+0000] {taskinstance.py:1382} INFO - Executing <Task(PythonOperator): Transform> on 2023-11-22 03:09:53.954584+00:00
[2023-11-22T03:10:00.350+0000] {standard_task_runner.py:57} INFO - Started process 360 to run task
[2023-11-22T03:10:00.352+0000] {standard_task_runner.py:84} INFO - Running: ['***', 'tasks', 'run', 'outcomes_dag', 'Transform', 'manual__2023-11-22T03:09:53.954584+00:00', '--job-id', '20', '--raw', '--subdir', 'DAGS_FOLDER/outcomes_dag.py', '--cfg-path', '/tmp/tmp4in2yq_2']
[2023-11-22T03:10:00.354+0000] {standard_task_runner.py:85} INFO - Job 20: Subtask Transform
[2023-11-22T03:10:00.382+0000] {task_command.py:416} INFO - Running <TaskInstance: outcomes_dag.Transform manual__2023-11-22T03:09:53.954584+00:00 [running]> on host 24b88ba10398
[2023-11-22T03:10:00.422+0000] {taskinstance.py:1662} INFO - Exporting env vars: AIRFLOW_CTX_DAG_OWNER='***' AIRFLOW_CTX_DAG_ID='outcomes_dag' AIRFLOW_CTX_TASK_ID='Transform' AIRFLOW_CTX_EXECUTION_DATE='2023-11-22T03:09:53.954584+00:00' AIRFLOW_CTX_TRY_NUMBER='1' AIRFLOW_CTX_DAG_RUN_ID='manual__2023-11-22T03:09:53.954584+00:00'
[2023-11-22T03:10:00.423+0000] {logging_mixin.py:154} INFO - Getting data from Cloud Storage
[2023-11-22T03:10:00.933+0000] {taskinstance.py:1937} ERROR - Task failed with exception
Traceback (most recent call last):
  File "/home/airflow/.local/lib/python3.8/site-packages/airflow/operators/python.py", line 192, in execute
    return_value = self.execute_callable()
  File "/home/airflow/.local/lib/python3.8/site-packages/airflow/operators/python.py", line 209, in execute_callable
    return self.python_callable(*self.op_args, **self.op_kwargs)
  File "/opt/airflow/dags/ETL/Transform.py", line 10, in transform_data
    new_data = pre_process(df)
  File "/opt/airflow/dags/ETL/Transform.py", line 23, in pre_process
    df["datetime"] = pd.to_datetime(df["datetime"])
  File "/home/airflow/.local/lib/python3.8/site-packages/pandas/core/frame.py", line 3761, in __getitem__
    indexer = self.columns.get_loc(key)
  File "/home/airflow/.local/lib/python3.8/site-packages/pandas/core/indexes/range.py", line 349, in get_loc
    raise KeyError(key)
KeyError: 'datetime'
[2023-11-22T03:10:00.946+0000] {taskinstance.py:1400} INFO - Marking task as FAILED. dag_id=outcomes_dag, task_id=Transform, execution_date=20231122T030953, start_date=20231122T031000, end_date=20231122T031000
[2023-11-22T03:10:00.954+0000] {standard_task_runner.py:104} ERROR - Failed to execute job 20 for task Transform ('datetime'; 360)
[2023-11-22T03:10:00.989+0000] {local_task_job_runner.py:228} INFO - Task exited with return code 1
