[2023-11-22T23:03:17.855+0000] {taskinstance.py:1159} INFO - Dependencies all met for dep_context=non-requeueable deps ti=<TaskInstance: outcomes_dag.Load_to_staging scheduled__2023-11-09T00:00:00+00:00 [queued]>
[2023-11-22T23:03:17.868+0000] {taskinstance.py:1159} INFO - Dependencies all met for dep_context=requeueable deps ti=<TaskInstance: outcomes_dag.Load_to_staging scheduled__2023-11-09T00:00:00+00:00 [queued]>
[2023-11-22T23:03:17.869+0000] {taskinstance.py:1361} INFO - Starting attempt 4 of 4
[2023-11-22T23:03:17.894+0000] {taskinstance.py:1382} INFO - Executing <Task(PythonOperator): Load_to_staging> on 2023-11-09 00:00:00+00:00
[2023-11-22T23:03:17.931+0000] {standard_task_runner.py:57} INFO - Started process 443 to run task
[2023-11-22T23:03:17.974+0000] {standard_task_runner.py:84} INFO - Running: ['***', 'tasks', 'run', 'outcomes_dag', 'Load_to_staging', 'scheduled__2023-11-09T00:00:00+00:00', '--job-id', '107', '--raw', '--subdir', 'DAGS_FOLDER/outcomes_dag.py', '--cfg-path', '/tmp/tmphk9o7u92']
[2023-11-22T23:03:17.993+0000] {standard_task_runner.py:85} INFO - Job 107: Subtask Load_to_staging
[2023-11-22T23:03:18.178+0000] {task_command.py:416} INFO - Running <TaskInstance: outcomes_dag.Load_to_staging scheduled__2023-11-09T00:00:00+00:00 [running]> on host 4b2f5af281f8
[2023-11-22T23:03:18.329+0000] {taskinstance.py:1662} INFO - Exporting env vars: AIRFLOW_CTX_DAG_OWNER='***' AIRFLOW_CTX_DAG_ID='outcomes_dag' AIRFLOW_CTX_TASK_ID='Load_to_staging' AIRFLOW_CTX_EXECUTION_DATE='2023-11-09T00:00:00+00:00' AIRFLOW_CTX_TRY_NUMBER='4' AIRFLOW_CTX_DAG_RUN_ID='scheduled__2023-11-09T00:00:00+00:00'
[2023-11-22T23:03:18.774+0000] {taskinstance.py:1937} ERROR - Task failed with exception
Traceback (most recent call last):
  File "/home/airflow/.local/lib/python3.8/site-packages/airflow/operators/python.py", line 192, in execute
    return_value = self.execute_callable()
  File "/home/airflow/.local/lib/python3.8/site-packages/airflow/operators/python.py", line 209, in execute_callable
    return self.python_callable(*self.op_args, **self.op_kwargs)
  File "/opt/airflow/dags/ETL/load.py", line 31, in data_to_staging
    load_job = client.load_table_from_uri(uri, table_ref, job_config=job_config)
  File "/home/airflow/.local/lib/python3.8/site-packages/google/cloud/bigquery/client.py", line 2375, in load_table_from_uri
    load_job._begin(retry=retry, timeout=timeout)
  File "/home/airflow/.local/lib/python3.8/site-packages/google/cloud/bigquery/job/base.py", line 693, in _begin
    api_response = client._call_api(
  File "/home/airflow/.local/lib/python3.8/site-packages/google/cloud/bigquery/client.py", line 808, in _call_api
    return call()
  File "/home/airflow/.local/lib/python3.8/site-packages/google/api_core/retry.py", line 366, in retry_wrapped_func
    return retry_target(
  File "/home/airflow/.local/lib/python3.8/site-packages/google/api_core/retry.py", line 204, in retry_target
    return target()
  File "/home/airflow/.local/lib/python3.8/site-packages/google/cloud/_http/__init__.py", line 494, in api_request
    raise exceptions.from_http_response(response)
google.api_core.exceptions.NotFound: 404 POST https://bigquery.googleapis.com/bigquery/v2/projects/dcsc-warehouse/jobs?prettyPrint=false: Not found: Dataset dcsc-warehouse:dcsc-warehouse.shelter_warehouse_schema
[2023-11-22T23:03:18.785+0000] {taskinstance.py:1400} INFO - Marking task as FAILED. dag_id=outcomes_dag, task_id=Load_to_staging, execution_date=20231109T000000, start_date=20231122T230317, end_date=20231122T230318
[2023-11-22T23:03:18.793+0000] {standard_task_runner.py:104} ERROR - Failed to execute job 107 for task Load_to_staging (404 POST https://bigquery.googleapis.com/bigquery/v2/projects/dcsc-warehouse/jobs?prettyPrint=false: Not found: Dataset dcsc-warehouse:dcsc-warehouse.shelter_warehouse_schema; 443)
[2023-11-22T23:03:18.812+0000] {local_task_job_runner.py:228} INFO - Task exited with return code 1
[2023-11-22T23:23:43.894+0000] {taskinstance.py:1159} INFO - Dependencies all met for dep_context=non-requeueable deps ti=<TaskInstance: outcomes_dag.Load_to_staging scheduled__2023-11-09T00:00:00+00:00 [queued]>
[2023-11-22T23:23:43.915+0000] {taskinstance.py:1159} INFO - Dependencies all met for dep_context=requeueable deps ti=<TaskInstance: outcomes_dag.Load_to_staging scheduled__2023-11-09T00:00:00+00:00 [queued]>
[2023-11-22T23:23:43.915+0000] {taskinstance.py:1361} INFO - Starting attempt 4 of 4
[2023-11-22T23:23:43.930+0000] {taskinstance.py:1382} INFO - Executing <Task(PythonOperator): Load_to_staging> on 2023-11-09 00:00:00+00:00
[2023-11-22T23:23:43.938+0000] {standard_task_runner.py:57} INFO - Started process 404 to run task
[2023-11-22T23:23:43.943+0000] {standard_task_runner.py:84} INFO - Running: ['***', 'tasks', 'run', 'outcomes_dag', 'Load_to_staging', 'scheduled__2023-11-09T00:00:00+00:00', '--job-id', '92', '--raw', '--subdir', 'DAGS_FOLDER/outcomes_dag.py', '--cfg-path', '/tmp/tmp2z9wytyo']
[2023-11-22T23:23:43.945+0000] {standard_task_runner.py:85} INFO - Job 92: Subtask Load_to_staging
[2023-11-22T23:23:44.081+0000] {task_command.py:416} INFO - Running <TaskInstance: outcomes_dag.Load_to_staging scheduled__2023-11-09T00:00:00+00:00 [running]> on host b410bfb4af5e
[2023-11-22T23:23:44.234+0000] {taskinstance.py:1662} INFO - Exporting env vars: AIRFLOW_CTX_DAG_OWNER='***' AIRFLOW_CTX_DAG_ID='outcomes_dag' AIRFLOW_CTX_TASK_ID='Load_to_staging' AIRFLOW_CTX_EXECUTION_DATE='2023-11-09T00:00:00+00:00' AIRFLOW_CTX_TRY_NUMBER='4' AIRFLOW_CTX_DAG_RUN_ID='scheduled__2023-11-09T00:00:00+00:00'
[2023-11-22T23:23:44.484+0000] {taskinstance.py:1937} ERROR - Task failed with exception
Traceback (most recent call last):
  File "/home/airflow/.local/lib/python3.8/site-packages/airflow/operators/python.py", line 192, in execute
    return_value = self.execute_callable()
  File "/home/airflow/.local/lib/python3.8/site-packages/airflow/operators/python.py", line 209, in execute_callable
    return self.python_callable(*self.op_args, **self.op_kwargs)
  File "/opt/airflow/dags/ETL/load.py", line 33, in data_to_staging
    load_job.result()  # Wait for the job to complete
  File "/home/airflow/.local/lib/python3.8/site-packages/google/cloud/bigquery/job/base.py", line 922, in result
    return super(_AsyncJob, self).result(timeout=timeout, **kwargs)
  File "/home/airflow/.local/lib/python3.8/site-packages/google/api_core/future/polling.py", line 261, in result
    raise self._exception
google.api_core.exceptions.BadRequest: 400 No schema specified on job or table.
[2023-11-22T23:23:44.522+0000] {taskinstance.py:1400} INFO - Marking task as FAILED. dag_id=outcomes_dag, task_id=Load_to_staging, execution_date=20231109T000000, start_date=20231122T232343, end_date=20231122T232344
[2023-11-22T23:23:44.535+0000] {standard_task_runner.py:104} ERROR - Failed to execute job 92 for task Load_to_staging (400 No schema specified on job or table.; 404)
[2023-11-22T23:23:44.583+0000] {local_task_job_runner.py:228} INFO - Task exited with return code 1
[2023-11-22T23:46:23.614+0000] {taskinstance.py:1159} INFO - Dependencies all met for dep_context=non-requeueable deps ti=<TaskInstance: outcomes_dag.Load_to_staging scheduled__2023-11-09T00:00:00+00:00 [queued]>
[2023-11-22T23:46:23.619+0000] {taskinstance.py:1159} INFO - Dependencies all met for dep_context=requeueable deps ti=<TaskInstance: outcomes_dag.Load_to_staging scheduled__2023-11-09T00:00:00+00:00 [queued]>
[2023-11-22T23:46:23.620+0000] {taskinstance.py:1361} INFO - Starting attempt 4 of 4
[2023-11-22T23:46:23.628+0000] {taskinstance.py:1382} INFO - Executing <Task(PythonOperator): Load_to_staging> on 2023-11-09 00:00:00+00:00
[2023-11-22T23:46:23.637+0000] {standard_task_runner.py:57} INFO - Started process 373 to run task
[2023-11-22T23:46:23.645+0000] {standard_task_runner.py:84} INFO - Running: ['***', 'tasks', 'run', 'outcomes_dag', 'Load_to_staging', 'scheduled__2023-11-09T00:00:00+00:00', '--job-id', '87', '--raw', '--subdir', 'DAGS_FOLDER/outcomes_dag.py', '--cfg-path', '/tmp/tmp5vpkic3p']
[2023-11-22T23:46:23.647+0000] {standard_task_runner.py:85} INFO - Job 87: Subtask Load_to_staging
[2023-11-22T23:46:23.691+0000] {task_command.py:416} INFO - Running <TaskInstance: outcomes_dag.Load_to_staging scheduled__2023-11-09T00:00:00+00:00 [running]> on host 371cae71aa63
[2023-11-22T23:46:23.745+0000] {taskinstance.py:1662} INFO - Exporting env vars: AIRFLOW_CTX_DAG_OWNER='***' AIRFLOW_CTX_DAG_ID='outcomes_dag' AIRFLOW_CTX_TASK_ID='Load_to_staging' AIRFLOW_CTX_EXECUTION_DATE='2023-11-09T00:00:00+00:00' AIRFLOW_CTX_TRY_NUMBER='4' AIRFLOW_CTX_DAG_RUN_ID='scheduled__2023-11-09T00:00:00+00:00'
[2023-11-22T23:46:24.155+0000] {taskinstance.py:1937} ERROR - Task failed with exception
Traceback (most recent call last):
  File "/home/airflow/.local/lib/python3.8/site-packages/airflow/operators/python.py", line 192, in execute
    return_value = self.execute_callable()
  File "/home/airflow/.local/lib/python3.8/site-packages/airflow/operators/python.py", line 209, in execute_callable
    return self.python_callable(*self.op_args, **self.op_kwargs)
  File "/opt/airflow/dags/ETL/load.py", line 33, in data_to_staging
    load_job.result()  # Wait for the job to complete
  File "/home/airflow/.local/lib/python3.8/site-packages/google/cloud/bigquery/job/base.py", line 922, in result
    return super(_AsyncJob, self).result(timeout=timeout, **kwargs)
  File "/home/airflow/.local/lib/python3.8/site-packages/google/api_core/future/polling.py", line 261, in result
    raise self._exception
google.api_core.exceptions.BadRequest: 400 No schema specified on job or table.
[2023-11-22T23:46:24.173+0000] {taskinstance.py:1400} INFO - Marking task as FAILED. dag_id=outcomes_dag, task_id=Load_to_staging, execution_date=20231109T000000, start_date=20231122T234623, end_date=20231122T234624
[2023-11-22T23:46:24.183+0000] {standard_task_runner.py:104} ERROR - Failed to execute job 87 for task Load_to_staging (400 No schema specified on job or table.; 373)
[2023-11-22T23:46:24.206+0000] {local_task_job_runner.py:228} INFO - Task exited with return code 1
[2023-11-23T00:42:58.953+0000] {taskinstance.py:1159} INFO - Dependencies all met for dep_context=non-requeueable deps ti=<TaskInstance: outcomes_dag.Load_to_staging scheduled__2023-11-09T00:00:00+00:00 [queued]>
[2023-11-23T00:42:58.960+0000] {taskinstance.py:1159} INFO - Dependencies all met for dep_context=requeueable deps ti=<TaskInstance: outcomes_dag.Load_to_staging scheduled__2023-11-09T00:00:00+00:00 [queued]>
[2023-11-23T00:42:58.960+0000] {taskinstance.py:1361} INFO - Starting attempt 4 of 4
[2023-11-23T00:42:58.972+0000] {taskinstance.py:1382} INFO - Executing <Task(PythonOperator): Load_to_staging> on 2023-11-09 00:00:00+00:00
[2023-11-23T00:42:58.986+0000] {standard_task_runner.py:57} INFO - Started process 416 to run task
[2023-11-23T00:42:59.001+0000] {standard_task_runner.py:84} INFO - Running: ['***', 'tasks', 'run', 'outcomes_dag', 'Load_to_staging', 'scheduled__2023-11-09T00:00:00+00:00', '--job-id', '101', '--raw', '--subdir', 'DAGS_FOLDER/outcomes_dag.py', '--cfg-path', '/tmp/tmp4ikkbq85']
[2023-11-23T00:42:59.019+0000] {standard_task_runner.py:85} INFO - Job 101: Subtask Load_to_staging
[2023-11-23T00:42:59.196+0000] {task_command.py:416} INFO - Running <TaskInstance: outcomes_dag.Load_to_staging scheduled__2023-11-09T00:00:00+00:00 [running]> on host 75913536581a
[2023-11-23T00:42:59.417+0000] {taskinstance.py:1662} INFO - Exporting env vars: AIRFLOW_CTX_DAG_OWNER='***' AIRFLOW_CTX_DAG_ID='outcomes_dag' AIRFLOW_CTX_TASK_ID='Load_to_staging' AIRFLOW_CTX_EXECUTION_DATE='2023-11-09T00:00:00+00:00' AIRFLOW_CTX_TRY_NUMBER='4' AIRFLOW_CTX_DAG_RUN_ID='scheduled__2023-11-09T00:00:00+00:00'
[2023-11-23T00:42:59.968+0000] {taskinstance.py:1937} ERROR - Task failed with exception
Traceback (most recent call last):
  File "/home/airflow/.local/lib/python3.8/site-packages/airflow/operators/python.py", line 192, in execute
    return_value = self.execute_callable()
  File "/home/airflow/.local/lib/python3.8/site-packages/airflow/operators/python.py", line 209, in execute_callable
    return self.python_callable(*self.op_args, **self.op_kwargs)
  File "/opt/airflow/dags/ETL/load.py", line 33, in data_to_staging
    load_job = client.load_table_from_uri(uri, table_ref, job_config=job_config)
  File "/home/airflow/.local/lib/python3.8/site-packages/google/cloud/bigquery/client.py", line 2375, in load_table_from_uri
    load_job._begin(retry=retry, timeout=timeout)
  File "/home/airflow/.local/lib/python3.8/site-packages/google/cloud/bigquery/job/base.py", line 693, in _begin
    api_response = client._call_api(
  File "/home/airflow/.local/lib/python3.8/site-packages/google/cloud/bigquery/client.py", line 808, in _call_api
    return call()
  File "/home/airflow/.local/lib/python3.8/site-packages/google/api_core/retry.py", line 366, in retry_wrapped_func
    return retry_target(
  File "/home/airflow/.local/lib/python3.8/site-packages/google/api_core/retry.py", line 204, in retry_target
    return target()
  File "/home/airflow/.local/lib/python3.8/site-packages/google/cloud/_http/__init__.py", line 494, in api_request
    raise exceptions.from_http_response(response)
google.api_core.exceptions.NotFound: 404 POST https://bigquery.googleapis.com/bigquery/v2/projects/dcsc-warehouse/jobs?prettyPrint=false: Not found: Dataset dcsc-warehouse:dcsc-warehouse.shelter_warehouse_schema
[2023-11-23T00:42:59.996+0000] {taskinstance.py:1400} INFO - Marking task as FAILED. dag_id=outcomes_dag, task_id=Load_to_staging, execution_date=20231109T000000, start_date=20231123T004258, end_date=20231123T004259
[2023-11-23T00:43:00.011+0000] {standard_task_runner.py:104} ERROR - Failed to execute job 101 for task Load_to_staging (404 POST https://bigquery.googleapis.com/bigquery/v2/projects/dcsc-warehouse/jobs?prettyPrint=false: Not found: Dataset dcsc-warehouse:dcsc-warehouse.shelter_warehouse_schema; 416)
[2023-11-23T00:43:00.071+0000] {local_task_job_runner.py:228} INFO - Task exited with return code 1
