[2023-11-22T23:00:02.800+0000] {taskinstance.py:1159} INFO - Dependencies all met for dep_context=non-requeueable deps ti=<TaskInstance: outcomes_dag.Load_to_staging scheduled__2023-11-13T00:00:00+00:00 [queued]>
[2023-11-22T23:00:02.859+0000] {taskinstance.py:1159} INFO - Dependencies all met for dep_context=requeueable deps ti=<TaskInstance: outcomes_dag.Load_to_staging scheduled__2023-11-13T00:00:00+00:00 [queued]>
[2023-11-22T23:00:02.864+0000] {taskinstance.py:1361} INFO - Starting attempt 1 of 4
[2023-11-22T23:00:02.971+0000] {taskinstance.py:1382} INFO - Executing <Task(PythonOperator): Load_to_staging> on 2023-11-13 00:00:00+00:00
[2023-11-22T23:00:02.994+0000] {standard_task_runner.py:57} INFO - Started process 232 to run task
[2023-11-22T23:00:03.035+0000] {standard_task_runner.py:84} INFO - Running: ['***', 'tasks', 'run', 'outcomes_dag', 'Load_to_staging', 'scheduled__2023-11-13T00:00:00+00:00', '--job-id', '53', '--raw', '--subdir', 'DAGS_FOLDER/outcomes_dag.py', '--cfg-path', '/tmp/tmpie2hh99l']
[2023-11-22T23:00:03.058+0000] {standard_task_runner.py:85} INFO - Job 53: Subtask Load_to_staging
[2023-11-22T23:00:03.316+0000] {task_command.py:416} INFO - Running <TaskInstance: outcomes_dag.Load_to_staging scheduled__2023-11-13T00:00:00+00:00 [running]> on host 4b2f5af281f8
[2023-11-22T23:00:03.870+0000] {taskinstance.py:1662} INFO - Exporting env vars: AIRFLOW_CTX_DAG_OWNER='***' AIRFLOW_CTX_DAG_ID='outcomes_dag' AIRFLOW_CTX_TASK_ID='Load_to_staging' AIRFLOW_CTX_EXECUTION_DATE='2023-11-13T00:00:00+00:00' AIRFLOW_CTX_TRY_NUMBER='1' AIRFLOW_CTX_DAG_RUN_ID='scheduled__2023-11-13T00:00:00+00:00'
[2023-11-22T23:00:04.846+0000] {taskinstance.py:1937} ERROR - Task failed with exception
Traceback (most recent call last):
  File "/home/airflow/.local/lib/python3.8/site-packages/airflow/operators/python.py", line 192, in execute
    return_value = self.execute_callable()
  File "/home/airflow/.local/lib/python3.8/site-packages/airflow/operators/python.py", line 209, in execute_callable
    return self.python_callable(*self.op_args, **self.op_kwargs)
  File "/opt/airflow/dags/ETL/load.py", line 31, in data_to_staging
    load_job = client.load_table_from_uri(uri, table_ref, job_config=job_config)
  File "/home/airflow/.local/lib/python3.8/site-packages/google/cloud/bigquery/client.py", line 2375, in load_table_from_uri
    load_job._begin(retry=retry, timeout=timeout)
  File "/home/airflow/.local/lib/python3.8/site-packages/google/cloud/bigquery/job/base.py", line 693, in _begin
    api_response = client._call_api(
  File "/home/airflow/.local/lib/python3.8/site-packages/google/cloud/bigquery/client.py", line 808, in _call_api
    return call()
  File "/home/airflow/.local/lib/python3.8/site-packages/google/api_core/retry.py", line 366, in retry_wrapped_func
    return retry_target(
  File "/home/airflow/.local/lib/python3.8/site-packages/google/api_core/retry.py", line 204, in retry_target
    return target()
  File "/home/airflow/.local/lib/python3.8/site-packages/google/cloud/_http/__init__.py", line 494, in api_request
    raise exceptions.from_http_response(response)
google.api_core.exceptions.NotFound: 404 POST https://bigquery.googleapis.com/bigquery/v2/projects/dcsc-warehouse/jobs?prettyPrint=false: Not found: Dataset dcsc-warehouse:dcsc-warehouse.shelter_warehouse_schema
[2023-11-22T23:00:04.925+0000] {taskinstance.py:1400} INFO - Marking task as UP_FOR_RETRY. dag_id=outcomes_dag, task_id=Load_to_staging, execution_date=20231113T000000, start_date=20231122T230002, end_date=20231122T230004
[2023-11-22T23:00:04.985+0000] {standard_task_runner.py:104} ERROR - Failed to execute job 53 for task Load_to_staging (404 POST https://bigquery.googleapis.com/bigquery/v2/projects/dcsc-warehouse/jobs?prettyPrint=false: Not found: Dataset dcsc-warehouse:dcsc-warehouse.shelter_warehouse_schema; 232)
[2023-11-22T23:00:05.091+0000] {local_task_job_runner.py:228} INFO - Task exited with return code 1
[2023-11-22T23:20:25.310+0000] {taskinstance.py:1159} INFO - Dependencies all met for dep_context=non-requeueable deps ti=<TaskInstance: outcomes_dag.Load_to_staging scheduled__2023-11-13T00:00:00+00:00 [queued]>
[2023-11-22T23:20:25.322+0000] {taskinstance.py:1159} INFO - Dependencies all met for dep_context=requeueable deps ti=<TaskInstance: outcomes_dag.Load_to_staging scheduled__2023-11-13T00:00:00+00:00 [queued]>
[2023-11-22T23:20:25.323+0000] {taskinstance.py:1361} INFO - Starting attempt 1 of 4
[2023-11-22T23:20:25.341+0000] {taskinstance.py:1382} INFO - Executing <Task(PythonOperator): Load_to_staging> on 2023-11-13 00:00:00+00:00
[2023-11-22T23:20:25.348+0000] {standard_task_runner.py:57} INFO - Started process 199 to run task
[2023-11-22T23:20:25.371+0000] {standard_task_runner.py:84} INFO - Running: ['***', 'tasks', 'run', 'outcomes_dag', 'Load_to_staging', 'scheduled__2023-11-13T00:00:00+00:00', '--job-id', '47', '--raw', '--subdir', 'DAGS_FOLDER/outcomes_dag.py', '--cfg-path', '/tmp/tmpk7ws_ycv']
[2023-11-22T23:20:25.380+0000] {standard_task_runner.py:85} INFO - Job 47: Subtask Load_to_staging
[2023-11-22T23:20:25.468+0000] {task_command.py:416} INFO - Running <TaskInstance: outcomes_dag.Load_to_staging scheduled__2023-11-13T00:00:00+00:00 [running]> on host b410bfb4af5e
[2023-11-22T23:20:25.541+0000] {taskinstance.py:1662} INFO - Exporting env vars: AIRFLOW_CTX_DAG_OWNER='***' AIRFLOW_CTX_DAG_ID='outcomes_dag' AIRFLOW_CTX_TASK_ID='Load_to_staging' AIRFLOW_CTX_EXECUTION_DATE='2023-11-13T00:00:00+00:00' AIRFLOW_CTX_TRY_NUMBER='1' AIRFLOW_CTX_DAG_RUN_ID='scheduled__2023-11-13T00:00:00+00:00'
[2023-11-22T23:20:25.905+0000] {taskinstance.py:1937} ERROR - Task failed with exception
Traceback (most recent call last):
  File "/home/airflow/.local/lib/python3.8/site-packages/airflow/operators/python.py", line 192, in execute
    return_value = self.execute_callable()
  File "/home/airflow/.local/lib/python3.8/site-packages/airflow/operators/python.py", line 209, in execute_callable
    return self.python_callable(*self.op_args, **self.op_kwargs)
  File "/opt/airflow/dags/ETL/load.py", line 33, in data_to_staging
    load_job.result()  # Wait for the job to complete
  File "/home/airflow/.local/lib/python3.8/site-packages/google/cloud/bigquery/job/base.py", line 922, in result
    return super(_AsyncJob, self).result(timeout=timeout, **kwargs)
  File "/home/airflow/.local/lib/python3.8/site-packages/google/api_core/future/polling.py", line 261, in result
    raise self._exception
google.api_core.exceptions.BadRequest: 400 No schema specified on job or table.
[2023-11-22T23:20:25.942+0000] {taskinstance.py:1400} INFO - Marking task as UP_FOR_RETRY. dag_id=outcomes_dag, task_id=Load_to_staging, execution_date=20231113T000000, start_date=20231122T232025, end_date=20231122T232025
[2023-11-22T23:20:25.966+0000] {standard_task_runner.py:104} ERROR - Failed to execute job 47 for task Load_to_staging (400 No schema specified on job or table.; 199)
[2023-11-22T23:20:26.026+0000] {local_task_job_runner.py:228} INFO - Task exited with return code 1
[2023-11-22T23:43:12.766+0000] {taskinstance.py:1159} INFO - Dependencies all met for dep_context=non-requeueable deps ti=<TaskInstance: outcomes_dag.Load_to_staging scheduled__2023-11-13T00:00:00+00:00 [queued]>
[2023-11-22T23:43:12.838+0000] {taskinstance.py:1159} INFO - Dependencies all met for dep_context=requeueable deps ti=<TaskInstance: outcomes_dag.Load_to_staging scheduled__2023-11-13T00:00:00+00:00 [queued]>
[2023-11-22T23:43:12.846+0000] {taskinstance.py:1361} INFO - Starting attempt 1 of 4
[2023-11-22T23:43:13.115+0000] {taskinstance.py:1382} INFO - Executing <Task(PythonOperator): Load_to_staging> on 2023-11-13 00:00:00+00:00
[2023-11-22T23:43:13.419+0000] {standard_task_runner.py:57} INFO - Started process 198 to run task
[2023-11-22T23:43:13.520+0000] {standard_task_runner.py:84} INFO - Running: ['***', 'tasks', 'run', 'outcomes_dag', 'Load_to_staging', 'scheduled__2023-11-13T00:00:00+00:00', '--job-id', '40', '--raw', '--subdir', 'DAGS_FOLDER/outcomes_dag.py', '--cfg-path', '/tmp/tmp0a_rnswf']
[2023-11-22T23:43:13.567+0000] {standard_task_runner.py:85} INFO - Job 40: Subtask Load_to_staging
[2023-11-22T23:43:14.143+0000] {task_command.py:416} INFO - Running <TaskInstance: outcomes_dag.Load_to_staging scheduled__2023-11-13T00:00:00+00:00 [running]> on host 371cae71aa63
[2023-11-22T23:43:14.908+0000] {taskinstance.py:1662} INFO - Exporting env vars: AIRFLOW_CTX_DAG_OWNER='***' AIRFLOW_CTX_DAG_ID='outcomes_dag' AIRFLOW_CTX_TASK_ID='Load_to_staging' AIRFLOW_CTX_EXECUTION_DATE='2023-11-13T00:00:00+00:00' AIRFLOW_CTX_TRY_NUMBER='1' AIRFLOW_CTX_DAG_RUN_ID='scheduled__2023-11-13T00:00:00+00:00'
[2023-11-22T23:43:15.401+0000] {taskinstance.py:1937} ERROR - Task failed with exception
Traceback (most recent call last):
  File "/home/airflow/.local/lib/python3.8/site-packages/airflow/operators/python.py", line 192, in execute
    return_value = self.execute_callable()
  File "/home/airflow/.local/lib/python3.8/site-packages/airflow/operators/python.py", line 209, in execute_callable
    return self.python_callable(*self.op_args, **self.op_kwargs)
  File "/opt/airflow/dags/ETL/load.py", line 33, in data_to_staging
    load_job.result()  # Wait for the job to complete
  File "/home/airflow/.local/lib/python3.8/site-packages/google/cloud/bigquery/job/base.py", line 922, in result
    return super(_AsyncJob, self).result(timeout=timeout, **kwargs)
  File "/home/airflow/.local/lib/python3.8/site-packages/google/api_core/future/polling.py", line 261, in result
    raise self._exception
google.api_core.exceptions.BadRequest: 400 No schema specified on job or table.
[2023-11-22T23:43:15.475+0000] {taskinstance.py:1400} INFO - Marking task as UP_FOR_RETRY. dag_id=outcomes_dag, task_id=Load_to_staging, execution_date=20231113T000000, start_date=20231122T234312, end_date=20231122T234315
[2023-11-22T23:43:15.632+0000] {standard_task_runner.py:104} ERROR - Failed to execute job 40 for task Load_to_staging (400 No schema specified on job or table.; 198)
[2023-11-22T23:43:15.675+0000] {local_task_job_runner.py:228} INFO - Task exited with return code 1
[2023-11-23T00:39:44.449+0000] {taskinstance.py:1159} INFO - Dependencies all met for dep_context=non-requeueable deps ti=<TaskInstance: outcomes_dag.Load_to_staging scheduled__2023-11-13T00:00:00+00:00 [queued]>
[2023-11-23T00:39:44.500+0000] {taskinstance.py:1159} INFO - Dependencies all met for dep_context=requeueable deps ti=<TaskInstance: outcomes_dag.Load_to_staging scheduled__2023-11-13T00:00:00+00:00 [queued]>
[2023-11-23T00:39:44.508+0000] {taskinstance.py:1361} INFO - Starting attempt 1 of 4
[2023-11-23T00:39:44.603+0000] {taskinstance.py:1382} INFO - Executing <Task(PythonOperator): Load_to_staging> on 2023-11-13 00:00:00+00:00
[2023-11-23T00:39:44.625+0000] {standard_task_runner.py:57} INFO - Started process 256 to run task
[2023-11-23T00:39:44.657+0000] {standard_task_runner.py:84} INFO - Running: ['***', 'tasks', 'run', 'outcomes_dag', 'Load_to_staging', 'scheduled__2023-11-13T00:00:00+00:00', '--job-id', '56', '--raw', '--subdir', 'DAGS_FOLDER/outcomes_dag.py', '--cfg-path', '/tmp/tmp4u9w8orf']
[2023-11-23T00:39:44.685+0000] {standard_task_runner.py:85} INFO - Job 56: Subtask Load_to_staging
[2023-11-23T00:39:44.856+0000] {task_command.py:416} INFO - Running <TaskInstance: outcomes_dag.Load_to_staging scheduled__2023-11-13T00:00:00+00:00 [running]> on host 75913536581a
[2023-11-23T00:39:45.192+0000] {taskinstance.py:1662} INFO - Exporting env vars: AIRFLOW_CTX_DAG_OWNER='***' AIRFLOW_CTX_DAG_ID='outcomes_dag' AIRFLOW_CTX_TASK_ID='Load_to_staging' AIRFLOW_CTX_EXECUTION_DATE='2023-11-13T00:00:00+00:00' AIRFLOW_CTX_TRY_NUMBER='1' AIRFLOW_CTX_DAG_RUN_ID='scheduled__2023-11-13T00:00:00+00:00'
[2023-11-23T00:39:45.972+0000] {taskinstance.py:1937} ERROR - Task failed with exception
Traceback (most recent call last):
  File "/home/airflow/.local/lib/python3.8/site-packages/airflow/operators/python.py", line 192, in execute
    return_value = self.execute_callable()
  File "/home/airflow/.local/lib/python3.8/site-packages/airflow/operators/python.py", line 209, in execute_callable
    return self.python_callable(*self.op_args, **self.op_kwargs)
  File "/opt/airflow/dags/ETL/load.py", line 33, in data_to_staging
    load_job = client.load_table_from_uri(uri, table_ref, job_config=job_config)
  File "/home/airflow/.local/lib/python3.8/site-packages/google/cloud/bigquery/client.py", line 2375, in load_table_from_uri
    load_job._begin(retry=retry, timeout=timeout)
  File "/home/airflow/.local/lib/python3.8/site-packages/google/cloud/bigquery/job/base.py", line 693, in _begin
    api_response = client._call_api(
  File "/home/airflow/.local/lib/python3.8/site-packages/google/cloud/bigquery/client.py", line 808, in _call_api
    return call()
  File "/home/airflow/.local/lib/python3.8/site-packages/google/api_core/retry.py", line 366, in retry_wrapped_func
    return retry_target(
  File "/home/airflow/.local/lib/python3.8/site-packages/google/api_core/retry.py", line 204, in retry_target
    return target()
  File "/home/airflow/.local/lib/python3.8/site-packages/google/cloud/_http/__init__.py", line 494, in api_request
    raise exceptions.from_http_response(response)
google.api_core.exceptions.NotFound: 404 POST https://bigquery.googleapis.com/bigquery/v2/projects/dcsc-warehouse/jobs?prettyPrint=false: Not found: Dataset dcsc-warehouse:dcsc-warehouse.shelter_warehouse_schema
[2023-11-23T00:39:46.037+0000] {taskinstance.py:1400} INFO - Marking task as UP_FOR_RETRY. dag_id=outcomes_dag, task_id=Load_to_staging, execution_date=20231113T000000, start_date=20231123T003944, end_date=20231123T003946
[2023-11-23T00:39:46.050+0000] {standard_task_runner.py:104} ERROR - Failed to execute job 56 for task Load_to_staging (404 POST https://bigquery.googleapis.com/bigquery/v2/projects/dcsc-warehouse/jobs?prettyPrint=false: Not found: Dataset dcsc-warehouse:dcsc-warehouse.shelter_warehouse_schema; 256)
[2023-11-23T00:39:46.108+0000] {local_task_job_runner.py:228} INFO - Task exited with return code 1
