[2023-11-23T01:16:53.748+0000] {taskinstance.py:1159} INFO - Dependencies all met for dep_context=non-requeueable deps ti=<TaskInstance: outcomes_dag.Load_to_staging scheduled__2023-11-20T00:00:00+00:00 [queued]>
[2023-11-23T01:16:53.752+0000] {taskinstance.py:1159} INFO - Dependencies all met for dep_context=requeueable deps ti=<TaskInstance: outcomes_dag.Load_to_staging scheduled__2023-11-20T00:00:00+00:00 [queued]>
[2023-11-23T01:16:53.752+0000] {taskinstance.py:1361} INFO - Starting attempt 10 of 12
[2023-11-23T01:16:53.758+0000] {taskinstance.py:1382} INFO - Executing <Task(PythonOperator): Load_to_staging> on 2023-11-20 00:00:00+00:00
[2023-11-23T01:16:53.763+0000] {standard_task_runner.py:57} INFO - Started process 1176 to run task
[2023-11-23T01:16:53.766+0000] {standard_task_runner.py:84} INFO - Running: ['***', 'tasks', 'run', 'outcomes_dag', 'Load_to_staging', 'scheduled__2023-11-20T00:00:00+00:00', '--job-id', '183', '--raw', '--subdir', 'DAGS_FOLDER/outcomes_dag.py', '--cfg-path', '/tmp/tmpxogvsyfc']
[2023-11-23T01:16:53.769+0000] {standard_task_runner.py:85} INFO - Job 183: Subtask Load_to_staging
[2023-11-23T01:16:53.810+0000] {task_command.py:416} INFO - Running <TaskInstance: outcomes_dag.Load_to_staging scheduled__2023-11-20T00:00:00+00:00 [running]> on host 75913536581a
[2023-11-23T01:16:53.857+0000] {taskinstance.py:1662} INFO - Exporting env vars: AIRFLOW_CTX_DAG_OWNER='***' AIRFLOW_CTX_DAG_ID='outcomes_dag' AIRFLOW_CTX_TASK_ID='Load_to_staging' AIRFLOW_CTX_EXECUTION_DATE='2023-11-20T00:00:00+00:00' AIRFLOW_CTX_TRY_NUMBER='10' AIRFLOW_CTX_DAG_RUN_ID='scheduled__2023-11-20T00:00:00+00:00'
[2023-11-23T01:16:56.074+0000] {taskinstance.py:1937} ERROR - Task failed with exception
Traceback (most recent call last):
  File "/home/airflow/.local/lib/python3.8/site-packages/airflow/operators/python.py", line 192, in execute
    return_value = self.execute_callable()
  File "/home/airflow/.local/lib/python3.8/site-packages/airflow/operators/python.py", line 209, in execute_callable
    return self.python_callable(*self.op_args, **self.op_kwargs)
  File "/opt/airflow/dags/ETL/load.py", line 41, in data_to_staging
    load_job.result()  # Wait for the job to complete
  File "/home/airflow/.local/lib/python3.8/site-packages/google/cloud/bigquery/job/base.py", line 922, in result
    return super(_AsyncJob, self).result(timeout=timeout, **kwargs)
  File "/home/airflow/.local/lib/python3.8/site-packages/google/api_core/future/polling.py", line 261, in result
    raise self._exception
google.api_core.exceptions.BadRequest: 400 Error while reading data, error message: CSV processing encountered too many errors, giving up. Rows: 51; errors: 51; max bad: 0; error percent: 0
[2023-11-23T01:16:56.102+0000] {taskinstance.py:1400} INFO - Marking task as UP_FOR_RETRY. dag_id=outcomes_dag, task_id=Load_to_staging, execution_date=20231120T000000, start_date=20231123T011653, end_date=20231123T011656
[2023-11-23T01:16:56.110+0000] {standard_task_runner.py:104} ERROR - Failed to execute job 183 for task Load_to_staging (400 Error while reading data, error message: CSV processing encountered too many errors, giving up. Rows: 51; errors: 51; max bad: 0; error percent: 0; 1176)
[2023-11-23T01:16:56.137+0000] {local_task_job_runner.py:228} INFO - Task exited with return code 1
