[2023-11-21T02:36:04.087+0000] {taskinstance.py:1159} INFO - Dependencies all met for dep_context=non-requeueable deps ti=<TaskInstance: outcomes_dag.load manual__2023-11-21T02:35:58.695230+00:00 [queued]>
[2023-11-21T02:36:04.116+0000] {taskinstance.py:1159} INFO - Dependencies all met for dep_context=requeueable deps ti=<TaskInstance: outcomes_dag.load manual__2023-11-21T02:35:58.695230+00:00 [queued]>
[2023-11-21T02:36:04.120+0000] {taskinstance.py:1361} INFO - Starting attempt 1 of 1
[2023-11-21T02:36:04.149+0000] {taskinstance.py:1382} INFO - Executing <Task(PythonOperator): load> on 2023-11-21 02:35:58.695230+00:00
[2023-11-21T02:36:04.174+0000] {standard_task_runner.py:57} INFO - Started process 83 to run task
[2023-11-21T02:36:04.227+0000] {standard_task_runner.py:84} INFO - Running: ['***', 'tasks', 'run', 'outcomes_dag', 'load', 'manual__2023-11-21T02:35:58.695230+00:00', '--job-id', '5', '--raw', '--subdir', 'DAGS_FOLDER/outcomes_dag.py', '--cfg-path', '/tmp/tmp_w9yrpdi']
[2023-11-21T02:36:04.308+0000] {standard_task_runner.py:85} INFO - Job 5: Subtask load
[2023-11-21T02:36:04.512+0000] {task_command.py:416} INFO - Running <TaskInstance: outcomes_dag.load manual__2023-11-21T02:35:58.695230+00:00 [running]> on host b875fa978b1e
[2023-11-21T02:36:07.318+0000] {taskinstance.py:1662} INFO - Exporting env vars: AIRFLOW_CTX_DAG_OWNER='***' AIRFLOW_CTX_DAG_ID='outcomes_dag' AIRFLOW_CTX_TASK_ID='load' AIRFLOW_CTX_EXECUTION_DATE='2023-11-21T02:35:58.695230+00:00' AIRFLOW_CTX_TRY_NUMBER='1' AIRFLOW_CTX_DAG_RUN_ID='manual__2023-11-21T02:35:58.695230+00:00'
[2023-11-21T02:36:07.638+0000] {taskinstance.py:1937} ERROR - Task failed with exception
Traceback (most recent call last):
  File "/home/airflow/.local/lib/python3.8/site-packages/airflow/operators/python.py", line 192, in execute
    return_value = self.execute_callable()
  File "/home/airflow/.local/lib/python3.8/site-packages/airflow/operators/python.py", line 209, in execute_callable
    return self.python_callable(*self.op_args, **self.op_kwargs)
  File "/opt/airflow/dags/ETL/load.py", line 11, in load_data
    data_to_staging(filename, engine)
  File "/opt/airflow/dags/ETL/load.py", line 19, in data_to_staging
    data = pd.read_parquet(filename)
  File "/home/airflow/.local/lib/python3.8/site-packages/pandas/io/parquet.py", line 509, in read_parquet
    return impl.read(
  File "/home/airflow/.local/lib/python3.8/site-packages/pandas/io/parquet.py", line 220, in read
    path_or_handle, handles, kwargs["filesystem"] = _get_path_or_handle(
  File "/home/airflow/.local/lib/python3.8/site-packages/pandas/io/parquet.py", line 110, in _get_path_or_handle
    handles = get_handle(
  File "/home/airflow/.local/lib/python3.8/site-packages/pandas/io/common.py", line 868, in get_handle
    handle = open(handle, ioargs.mode)
FileNotFoundError: [Errno 2] No such file or directory: '/opt/airflow/data/2023-11-21/processed/transformed_shelter_data.parquet'
[2023-11-21T02:36:07.759+0000] {taskinstance.py:1400} INFO - Marking task as FAILED. dag_id=outcomes_dag, task_id=load, execution_date=20231121T023558, start_date=20231121T023604, end_date=20231121T023607
[2023-11-21T02:36:07.826+0000] {standard_task_runner.py:104} ERROR - Failed to execute job 5 for task load ([Errno 2] No such file or directory: '/opt/airflow/data/2023-11-21/processed/transformed_shelter_data.parquet'; 83)
[2023-11-21T02:36:08.013+0000] {local_task_job_runner.py:228} INFO - Task exited with return code 1
[2023-11-21T02:36:08.311+0000] {taskinstance.py:2778} INFO - 0 downstream tasks scheduled from follow-on schedule check
