[2023-11-21T02:24:03.708+0000] {taskinstance.py:1159} INFO - Dependencies all met for dep_context=non-requeueable deps ti=<TaskInstance: outcomes_dag.load manual__2023-11-21T01:20:06.921070+00:00 [queued]>
[2023-11-21T02:24:03.715+0000] {taskinstance.py:1159} INFO - Dependencies all met for dep_context=requeueable deps ti=<TaskInstance: outcomes_dag.load manual__2023-11-21T01:20:06.921070+00:00 [queued]>
[2023-11-21T02:24:03.715+0000] {taskinstance.py:1361} INFO - Starting attempt 2 of 2
[2023-11-21T02:24:03.723+0000] {taskinstance.py:1382} INFO - Executing <Task(PythonOperator): load> on 2023-11-21 01:20:06.921070+00:00
[2023-11-21T02:24:03.732+0000] {standard_task_runner.py:57} INFO - Started process 1294 to run task
[2023-11-21T02:24:03.741+0000] {standard_task_runner.py:84} INFO - Running: ['***', 'tasks', 'run', 'outcomes_dag', 'load', 'manual__2023-11-21T01:20:06.921070+00:00', '--job-id', '66', '--raw', '--subdir', 'DAGS_FOLDER/outcomes_dag.py', '--cfg-path', '/tmp/tmpsw8dpdn6']
[2023-11-21T02:24:03.756+0000] {standard_task_runner.py:85} INFO - Job 66: Subtask load
[2023-11-21T02:24:03.824+0000] {task_command.py:416} INFO - Running <TaskInstance: outcomes_dag.load manual__2023-11-21T01:20:06.921070+00:00 [running]> on host f31a30014ab0
[2023-11-21T02:24:04.368+0000] {taskinstance.py:1662} INFO - Exporting env vars: AIRFLOW_CTX_DAG_OWNER='***' AIRFLOW_CTX_DAG_ID='outcomes_dag' AIRFLOW_CTX_TASK_ID='load' AIRFLOW_CTX_EXECUTION_DATE='2023-11-21T01:20:06.921070+00:00' AIRFLOW_CTX_TRY_NUMBER='2' AIRFLOW_CTX_DAG_RUN_ID='manual__2023-11-21T01:20:06.921070+00:00'
[2023-11-21T02:24:04.656+0000] {logging_mixin.py:154} INFO - Data is in Staging Table...
[2023-11-21T02:24:04.657+0000] {taskinstance.py:1937} ERROR - Task failed with exception
Traceback (most recent call last):
  File "/home/airflow/.local/lib/python3.8/site-packages/airflow/operators/python.py", line 192, in execute
    return_value = self.execute_callable()
  File "/home/airflow/.local/lib/python3.8/site-packages/airflow/operators/python.py", line 209, in execute_callable
    return self.python_callable(*self.op_args, **self.op_kwargs)
  File "/opt/airflow/dags/ETL/load.py", line 13, in load_data
    execute_sql_script(engine)
  File "/opt/airflow/dags/ETL/load.py", line 38, in execute_sql_script
    with open(script_path, 'r') as file:
FileNotFoundError: [Errno 2] No such file or directory: '/ETL/data_insertion.sql'
[2023-11-21T02:24:04.669+0000] {taskinstance.py:1400} INFO - Marking task as FAILED. dag_id=outcomes_dag, task_id=load, execution_date=20231121T012006, start_date=20231121T022403, end_date=20231121T022404
[2023-11-21T02:24:04.675+0000] {standard_task_runner.py:104} ERROR - Failed to execute job 66 for task load ([Errno 2] No such file or directory: '/ETL/data_insertion.sql'; 1294)
[2023-11-21T02:24:04.713+0000] {local_task_job_runner.py:228} INFO - Task exited with return code 1
[2023-11-21T02:24:04.727+0000] {taskinstance.py:2778} INFO - 0 downstream tasks scheduled from follow-on schedule check
